Workbook

Sheet 총괄표
B3: CCTV 연계 운영 현황 | H3: 방범용 CCTV 년도별 현황
B4: 일련번호 | C4: 구분 | D4: 개소 | E4: 대수 | F4: 비고 | H4: 년도 | I4: 개소 | J4: 대수 | K4: 비고 | L4: 교체현황(년도별_노후cctv교체현황) | X4: 비고
C5: 합계 | D5: =SUM(D6:D14) -> 1308 | E5: =SUM(E6:E14) -> 4155 | L5: 2016 | M5: 2017 | N5: 2018 | O5: 2019 | P5: 2020 | Q5: 2021 | R5: 2022 | S5: 2023 상반기 | T5: 2023 하반기 | U5: 2024 상반기 | V5: 2024 하반기 | W5: 2025 상반기
B6: 1 | C6: 방범용 | D6: =방범!A3 -> 1000 | E6: =방범!F3 -> 3432 | F6: - 범죄취약지 : 2개소 8대 - 지능형 : 9개소 31대 - 노후 교체 화각중복 -3대 - 관리번호 327 -1대(수리불가로 화각조정) | H6: 합계 | I6: =SUM(I7:I25) -> 1000 | J6: =SUM(J7:J25) -> 3432 | K6: 2015년 이전 교체 | L6: =SUM(L7:L24) -> 45 | M6: =SUM(M7:M24) -> 30 | N6: =SUM(N7:N24) -> 69 | O6: =SUM(O7:O24) -> 63 | P6: =SUM(P7:P24) -> 65 | Q6: =SUM(Q7:Q24) -> 56 | R6: =SUM(R7:R24) -> 17 | S6: =SUM(S7:S24) -> 21 | ... W6: =SUM(W7:W24) -> 30
B7: 2 | C7: 교통상황수집 | D7: =교통상황수집!A4 -> 46 | E7: =교통상황수집!G4 -> 58 | H7: 2010이전 | I7: 39 | J7: 103 | L7: 11 | M7: 11 | N7: 15 | O7: 9 | T7: 5 | U7: 1
B8: 3 | C8: 차량번호인식 | D8: ='차량번호-수정'!A4 -> 19 | E8: =__xlnm._FilterDatabase79[대수] -> 26 | H8: 2011 | I8: 33 | J8: 112 | L8: 15 | M8: 17 | N8: 54 | O8: 12 | P8: 8 | Q8: 2 | T8: 4 | U8: 5
B9: 4 | C9: 초등학교 연계 | D9: ='초등학교_관리번호 재 부여'!A4 -> 43 | E9: ='초등학교_관리번호 재 부여'!$G$4 -> 260 | H9: 2012 | I9: 36 | J9: 123 | L9: 15 | M9: 2 | O9: 27 | P9: 57 | S9: 4 | T9: 2
B10: 5 | C10: 재난재해 연계 | D10: =재난재해!A4 -> 53 | E10: =재난재해!$G$4 -> 78 | H10: 2013 | I10: 66 | J10: 229 | O10: 15 | Q10: 32 | R10: 7 | S10: 13 | T10: 65 | U10: 6 | V10: 23 | W10: 21
B11: 6 | C11: 시설물 연계 | D11: =시설물!A4 -> 11 | E11: =시설물!$G$4 -> 11 | H11: 2014 | I11: 63 | J11: 216 | Q11: 22 | R11: 10 | S11: 2 | T11: 22 | U11: 17 | V11: 26 | W11: 7
B12: 7 | C12: 주정차 연계 | D12: =주정차!A3 -> 76 | E12: =주정차!$F$3 -> 230 | F12: 교통정책과-7573호(25.03.24.) 5개소 14대 연계 요청 | H12: 2015 | I12: 94 | J12: 319 | S12: 2 | T12: 5 | U12: 6 | V12: 10 | W12: 2
B13: 8 | C13: 교차로신호등연계 | D13: =신호등교차로cctv!A2 -> 51 | E13: =신호등교차로cctv!E2 -> 51 | H13: 2016 | I13: 93 | J13: 308 | L13: 4 | U13: 3
B14: 9 | C14: VDS | D14: =VDS!A4 -> 9 | E14: =__xlnm._FilterDatabase8310[대수] -> 9 | H14: 2017 | I14: 60 | J14: 208 | T14: 1
H15: 2018 | I15: 95 | J15: 338
H16: 2019 | I16: 53 | J16: 209
H17: 2020 | I17: 50 | J17: 181
H18: 2021 | I18: 57 | J18: 188
H19: 2022 | I19: 67 | J19: 216
H20: 2022 사송 | I20: 17 | J20: 73
H21: 2023 | I21: 80 | J21: 242 | U21: 2
H22: 2023 사송 | I22: 16 | J22: 72
H23: 2024 | I23: 39 | J23: 128
H24: 2024 사송 | I24: 31 | J24: 128
H25: 2025 | I25: 11 | J25: 39 | X25: 범죄취약지 CCTV : 2개소 8대 신규설치 지능형 CCTV : 9개소 31대 신규설치

Sheet 방범
A2: 개소 | B2: 관리 번호 | C2: 관리부서 | D2: 행정동 | E2: 카메라명 | F2: 대수 | G2: PTZ (회전) | H2: 고정 | I2: 실제설치장소(주변) | J2: 설치년도 | K2: 설치년월 | L2: 변경년도 | M2: 위도 | N2: 경도 | O2: 설치목적
A3: =SUM(A4:A1068) -> 1000 | F3: =SUM(F4:F1068) -> 3432 | G3: =SUM(G4:G1068) -> 787 | H3: =SUM(H4:H1068) -> 2645
A4: 1 | B4: 1 | C4: 정보통신과 | D4: 중앙동 | E4: 양산종합운동장(정문) | F4: =SUM(G4,H4) -> 3 | G4: 1 | H4: 2 | I4: 운동장 커피숍 앞 | J4: 2013 | K4: 2013.12 | L4: 2023.12 | M4: 35.34438 | N4: 129.03354 | O4: 생활방범
A5: 1 | B5: 2 | C5: 정보통신과 | D5: 중앙동 | E5: 양산종합운동장(보조구장) | F5: =SUM(G5,H5) -> 3 | G5: 1 | H5: 2 | I5: 흡연부스 옆 | J5: 2013 | K5: 2013.12 | L5: 2023.12 | M5: 35.345156 | N5: 129.03364 | O5: 생활방범
A6: 1 | B6: 3 | C6: 정보통신과 | D6: 삼성동 | E6: 한전사거리 | F6: =SUM(G6,H6) -> 4 | G6: 1 | H6: 3 | I6: 신기동 123-5(안전빌라) | J6: 2013 | K6: 2013.12 | L6: 2023.12 | M6: 35.354333 | N6: 129.0475 | O6: 생활방범
A7: 1 | B7: 4 | C7: 정보통신과 | D7: 삼성동 | E7: 조일빌라 | F7: =SUM(G7,H7) -> 2 | G7: - | H7: 2 | I7: 신기동 179(등산로입구) | J7: 2012 | K7: 2022.06 | L7: 2022.03 | M7: 35.354119 | N7: 129.04886 | O7: 생활방범
A8: 1 | B8: 5 | C8: 정보통신과 | D8: 중앙동 | E8: 중앙일보지국사거리 | F8: =SUM(G8,H8) -> 3 | G8: 1 | H8: 2 | I8: 남부동 466-4(중앙일보 앞) | J8: 2013 | K8: 2013.12 | L8: 2023.12 | M8: 35.337299 | N8: 129.03807 | O8: 생활방범
A9: 1 | B9: 6 | C9: 정보통신과 | D9: 중앙동 | E9: 중부동교육청 | F9: =SUM(G9,H9) -> 4 | G9: 1 | H9: 3 | I9: 남부동 297-7(원광어린이집 앞) | J9: 2010 | K9: 2021.03 | L9: 2021.03 | M9: 35.342151 | N9: 129.03874 | O9: 생활방범
A10: 1 | B10: 7 | C10: 정보통신과 | D10: 중앙동 | E10: 국민건강보험사거리 | F10: =SUM(G10,H10) -> 4 | G10: 1 | H10: 3 | I10: 중부동 604-5(국민건강보험공단 앞) | J10: 2013 | K10: 2013 | L10: 2019.12 | M10: 35.340436 | N10: 129.03354 | O10: 어린이보호
A11: 1 | B11: 8 | C11: 정보통신과 | D11: 중앙동 | E11: 남부2리마을회관 | F11: =SUM(G11,H11) -> 3 | G11: 1 | H11: 2 | I11: 남부동 455-4(남부2리 마을회관 맞은편) | J11: 2013 | K11: 2013.12 | L11: 2023.12 | M11: 35.339784 | N11: 129.03364 | O11: 생활방범
A12: 1 | B12: 13 | C12: 정보통신과 | D12: 양주동 | E12: 양주초등학교 | F12: =SUM(G12,H12) -> 3 | G12: 0 | H12: 3 | I12: 중부동 727(양주초등학교 정문 맞은 편) | J12: 2016 | K12: 2016.12 | L12: 2016.12 | M12: 35.342352 | N12: 129.0475 | O12: 어린이보호
A13: 1 | B13: 14 | C13: 정보통신과 | D13: 물금읍 | E13: 황산초등학교 | F13: =SUM(G13,H13) -> 3 | G13: - | H13: 3 | I13: 범어리 2716-15(물금 민원사무소 맞은 편 일신건영휴먼아파트 108동 앞) | J13: 2013 | K13: 2013 | L13: 2023.03 | M13: 35.331713 | N13: 129.04886 | O13: 어린이보호
A14: 1 | B14: 15 | C14: 정보통신과 | D14: 서창동 | E14: 북부사거리 | F14: =SUM(G14,H14) -> 2 | G14: - | H14: 2 | I14: 삼호동 201-2(GS25편의점 맞은 편) | J14: 2016 | K14: 2016.12 | L14: 2016.12 | M14: 35.419789 | N14: 129.03807 | O14: 생활방범
A15: 1 | B15: 16 | C15: 정보통신과 | D15: 양주동 | E15: 양주동행정복지센터 앞 횡단보도 (주정차 폴) | F15: =SUM(G15,H15) -> 2 | G15: - | H15: 2 | I15: 중부동 697-3(양주동행정복지센터 앞 횡단보도) | J15: 2010 | K15: 2021.03 | L15: 2024.05 | M15: 35.336736 | N15: 129.03874 | O15: 어린이보호
A16: 1 | B16: 17 | C16: 정보통신과 | D16: 양주동 | E16: 신양초등학교 | F16: =SUM(G16,H16) -> 3 | G16: - | H16: 3 | I16: 남부동 888(신양초에서 하천공원 쪽 횓단보도 옆) | J16: 2012 | K16: 2022.03 | L16: 2022.03 | M16: 35.333222 | N16: 129.03597 | O16: 어린이보호
A17: 1 | B17: 18 | C17: 정보통신과 | D17: 양주동 | E17: 파리바게뜨 맞은편 (주정차 폴) | F17: =SUM(G17,H17) -> 2 | G17: - | H17: 2 | I17: 남부동 565-2(벽산블루밍아파트 102동 앞 파리바게트 맞은 편) | J17: 2010 | K17: 2021.03 | L17: 2024.05 | M17: 35.331739 | N17: 129.03828 | O17: 어린이보호
A18: 1 | B18: 19 | C18: 정보통신과 | D18: 삼성동 | E18: 삼성초등학교 | F18: =SUM(G18,H18) -> 3 | G18: - | H18: 3 | I18: 북정동 408-3(원룸영하우스 맞은 편) | J18: 2013 | K18: 2013.10 | L18: 2023.12 | M18: 35.364551 | N18: 129.03263 | O18: 어린이보호
A19: 1 | B19: 20 | C19: 정보통신과 | D19: 물금읍 | E19: 범어근린공원 | F19: =SUM(G19,H19) -> 4 | G19: - | H19: 4 | I19: 범어근린공원 | J19: 2010 | K19: 2021 | L19: 2024.05 | M19: 35.329655 | N19: 129.00005 | O19: 어린이보호
A20: 1 | B20: 22 | C20: 정보통신과 | D20: 물금읍 | E20: 현대아파트 108동 옆 오봉초등학교 입구 사거리 (주정차 폴) | F20: =SUM(G20,H20) -> 1 | G20: - | H20: 1 | I20: 물금읍 범어리 682-1(현대아파트 108동 옆 오봉초등학교 입구 사거리) | J20: 2013 | K20: 2013.10. | L20: 2024.05 | M20: 35.335108 | N20: 129.17638 | O20: 어린이보호
A21: 1 | B21: 23 | C21: 정보통신과 | D21: 물금읍 | E21: 서남초등학교 | F21: =SUM(G21,H21) -> 3 | G21: - | H21: 3 | I21: 범어리 549(덕산아파트 101동 옆 횡단보도 근처) | J21: 2013 | K21: 2013.10 | L21: 2023.03 | M21: 35.327972 | N21: 129.03219 | O21: 어린이보호
A22: 1 | B22: 24 | C22: 정보통신과 | D22: 소주동 | E22: 백동초등학교 | F22: =SUM(G22,H22) -> 3 | G22: - | H22: 3 | I22: 소주동 1239-211(다모아DDC마트 맞은 편) | J22: 2013 | K22: 2013.10. | L22: 2024.11 | M22: 35.406602 | N22: 129.02335 | O22: 어린이보호
A23: 1 | B23: 25 | C23: 정보통신과 | D23: 서창동 | E23: 대운초등학교 | F23: =SUM(G23,H23) -> 3 | G23: - | H23: 3 | I23: 삼호동 885-5(쟌피오메르 맞은 편) | J23: 2013 | K23: 2013.10. | L23: 2025.05 | M23: 35.408749 | N23: 129.0283 | O23: 어린이보호
A24: 1 | B24: 26 | C24: 정보통신과 | D24: 평산동 | E24: 평산초등학교 | F24: =SUM(G24,H24) -> 4 | G24: - | H24: 4 | I24: 평산동 51-75(미래빌 앞) | J24: 2010 | K24: 2021 | L24: 2019.12 | M24: 35.385916 | N24: 129.048 | O24: 어린이보호
A25: 1 | B25: 27 | C25: 정보통신과 | D25: 평산동 | E25: 천성초등학교 | F25: =SUM(G25,H25) -> 3 | G25: - | H25: 3 | I25: 평산동 361(굽네치킨 앞) | J25: 2010 | K25: 2021.03 | L25: 2021.03 | M25: 35.379872 | N25: 129.0421 | O25: 어린이보호
A26: 1 | B26: 28 | C26: 정보통신과 | D26: 양주동 | E26: 양산지하철역 | F26: =SUM(G26,H26) -> 2 | G26: 1 | H26: 1 | I26: 중부동 655-1(리더스공인중개사 옆) | J26: 2009 | K26: 2017.07 | L26: 2024.03 | M26: 35.342772 | N26: 129.00576 | O26: 생활방범
A27: 1 | B27: 29 | C27: 정보통신과 | D27: 양주동 | E27: 양산시외버스터미널 | F27: =SUM(G27,H27) -> 2 | G27: - | H27: 2 | I27: 중부동 710-2(양산터미널 스타벅스 앞) | J27: 2015 | K27: 2015.1 | L27: 2015.1. | M27: 35.335472 | N27: 128.99796 | O27: 생활방범
A28: 1 | B28: 30 | C28: 정보통신과 | D28: 소주동 | E28: 주남저수지 인근 | F28: =SUM(G28,H28) -> 3 | G28: - | H28: 3 | I28: 주남저수지 인근 | J28: 2017 | K28: 2017 | L28: 2024.05 | M28: 35.426228 | N28: 129.14965 | O28: 어린이보호
A29: 1 | B29: 31 | C29: 정보통신과 | D29: 덕계동 | E29: 덕계초등학교 | F29: =SUM(G29,H29) -> 3 | G29: 1 | H29: 2 | I29: 덕계동 724-7(T world 앞) | J29: 2017 | K29: 2018 | L29: 2017.08. 2018.05. | M29: 35.374928 | N29: 129.1728 | O29: 어린이보호
A30: 1 | B30: 32 | C30: 정보통신과 | D30: 덕계동 | E30: 꽃피는시골그집 | F30: =SUM(G30,H30) -> 3 | G30: - | H30: 3 | I30: 꽃피는시골그집 앞 삼거리 | J30: 2014 | K30: 2014 | L30: 2024.05 | M30: 34.965534 | N30: 127.48671 | O30: 어린이보호
A31: 1 | B31: 33 | C31: 정보통신과 | D31: 물금읍 | E31: 명성빌라 | F31: =SUM(G31,H31) -> 4 | G31: - | H31: 4 | I31: 가촌리 555-1(명성빌라 맞은편) | J31: 2010 | K31: 2021.03 | L31: 2021.03 | M31: 35.322033 | N31: 129.1457 | O31: 생활방범
A32: 1 | B32: 34 | C32: 정보통신과 | D32: 서창동 | E32: 서창고교 | F32: =SUM(G32,H32) -> 3 | G32: 1 | H32: 2 | I32: 삼호동 758-10(한창원롬 입구) | J32: 2009 | K32: 2018.06 | L32: 2017.08. 2018.05. | M32: 35.413261 | N32: 129.17359 | O32: 생활방범
A33: 1 | B33: 35 | C33: 정보통신과 | D33: 삼성동 | E33: 한국전력 | F33: =SUM(G33,H33) -> 3 | G33: 1 | H33: 2 | I33: 신기동 276-8(로얄파크빌리지 4차 맞은 편) | J33: 2009 | K33: 2018.06 | L33: 2017.08. 2018.05. | M33: 35.352611 | N33: 129.0464 | O33: 생활방범
A34: 1 | B34: 36 | C34: 정보통신과 | D34: 삼성동 | E34: 북정동 버스종점 | F34: =SUM(G34,H34) -> 3 | G34: 1 | H34: 2 | I34: 북정동 846-13(남양매직 공장 입구) | J34: 2017 | K34: 2018.06 | L34: 2017.08. 2018.05. | M34: 35.365 | N34: 129.04977 | O34: 생활방범
A35: 1 | B35: 37 | C35: 정보통신과 | D35: 평산동 | E35: 평산초교 | F35: =SUM(G35,H35) -> 4 | G35: 1 | H35: 3 | I35: 평산동 41(소리엘피아노 맞은 편) | J35: 2017 | K35: 2018.06 | L35: 2017.08. 2018.05. | M35: 35.38591 | N35: 129.15305 | O35: 어린이보호
A36: 1 | B36: 38 | C36: 정보통신과 | D36: 상북면 | E36: 내석마을 | F36: =SUM(G36,H36) -> 2 | G36: 1 | H36: 1 | I36: 상북면 내석리 561-1((내석노인정 옆) | J36: 2017 | K36: 2018.06 | L36: 2017.08. 2018.05. | M36: 35.449348 | N36: 129.02084 | O36: 생활방범
A37: 1 | B37: 39 | C37: 정보통신과 | D37: 삼성동 | E37: 신기초등학교 | F37: =SUM(G37,H37) -> 2 | G37: 1 | H37: 1 | I37: 신기동 511-6(바푸리숯불김밥 맞은 편) | J37: 2017 | K37: 2018.06 | L37: 2017.08. 2018.05. | M37: 35.352424 | N37: 129.04119 | O37: 어린이보호
A38: 1 | B38: 40 | C38: 정보통신과 | D38: 동면 | E38: 동산초등학교 | F38: =SUM(G38,H38) -> 2 | G38: 1 | H38: 1 | I38: 금산리 771-2(동산초 입구 버스정류장 옆) | J38: 2010 | K38: 2017.07 | L38: 2017.8. | M38: 35.303898 | N38: 129.02515 | O38: 어린이보호
A39: 1 | B39: 41 | C39: 정보통신과 | D39: 물금읍 | E39: 물금초등학교 | F39: =SUM(G39,H39) -> 2 | G39: - | H39: 2 | I39: 물금읍 가촌리 1318-8(민스모터스 맞은 편) | J39: 2010 | K39: 2010 | L39: 2019.12 | M39: 35.315626 | N39: 128.99009 | O39: 어린이보호
A40: 1 | B40: 42 | C40: 정보통신과 | D40: 강서동 | E40: 어곡초등학교 | F40: =SUM(G40,H40) -> 2 | G40: - | H40: 2 | I40: 어곡동 182-8(동아식당 맞은 편) | J40: 2010 | K40: 2010 | L40: 2017.02. | M40: 35.315606 | N40: 129.027 | O40: 어린이보호
A41: 1 | B41: 43 | C41: 정보통신과 | D41: 원동면 | E41: 화제초등학교 | F41: =SUM(G41,H41) -> 2 | G41: - | H41: 2 | I41: 화제리 2041-4(화제초 입구 삼거리) | J41: 2010 | K41: 2010 | L41: 2017.02. | M41: 35.351619 | N41: 128.97708 | O41: 어린이보호
...

Sheet 차량번호-수정
A3: 개소 | B3: 구분 | C3: 관리번호 | D3: 관리부서 | E3: 행정동 | F3: 카메라명 | G3: 대수 | H3: 차선 | I3: 계량기번호 | J3: 설치 지번 | K3: 실제설치장소(주변) | L3: 설치년도 | M3: 위도 | N3: 경도
A4: =SUM(A5:A23) -> 19 | G4: =SUM(G5:G23) -> 26 | H4: =SUM(H5:H23) -> 45
A5: 1 | B5: 차번인식-1 | C5: 1001 | D5: 정보통신과 | E5: 동면 | F5: 동면 개곡-부산 경계 (노포방면) | G5: 1 | H5: 2 | I5: 02171515857 | J5: 동면 개곡리 72-4 | K5: 신설 | L5: 2015.11. 2020.10 | M5: 35.350755 | N5: 129.13335
A6: 1 | B6: 차번인식-2 | C6: 1002 | D6: 정보통신과 | E6: 하북면 | F6: 하북IC 인근(하북-울산 경계) | G6: 1 | H6: 2 | I6: 06190292992 | J6: 하북면 순지리 179-44 | K6: 신설 | L6: 2015.11. 2020.10 | M6: 35.495307 | N6: 129.09099
A7: 1 | B7: 차번인식-3 | C7: 1003 | D7: 정보통신과 | E7: 동면 | F7: 동면 사송-부산 경계 (노포방면) | G7: 2 | H7: 3 | I7: 56172217520 | J7: 동면 사송리 80 | L7: 2009.1.(2) 2014.12.(1) 2020.10(2) | M7: 35.299031 | N7: 129.0808
A8: 1 | B8: 차번인식-4 | C8: 1004 | D8: 정보통신과 | E8: 동면 | F8: 동면 호포-부산 경계 (호포방면) | G8: 2 | H8: 3 | J8: 동면 가산리 1202-38 | K8: 교체 | L8: . | M8: 35.275987 | N8: 129.01722
A9: 1 | B9: 차번인식-5 | C9: 1005 | D9: 정보통신과 | E9: 서창동 | F9: 회야교(웅상-울산 경계) | G9: 1 | H9: 2 | I9: 48171313918 | J9: 용당동 25-9 | L9: 2010 | M9: 35.434346 | N9: 129.19021
A10: 1 | B10: 차번인식-6 | C10: 1008 | D10: 정보통신과 | E10: 원동면 | F10: 원동-삼랑진 경계 | G10: 1 | H10: 2 | I10: 57170151541 | J10: 원동면 용당리 산 188-1 | K10: 신설 | L10: 2014.12. | M10: 35.401928 | N10: 128.88536
A11: 1 | B11: 차번인식-7 | C11: 1009 | D11: 정보통신과 | E11: 원동면 | F11: 배내골-울산 경계 | G11: 1 | H11: 2 | I11: 57170012626 | J11: 원동면 선리 45-1 | K11: 신설 | L11: 2014.12. | M11: 35.527842 | N11: 129.00952
A12: 1 | B12: 차번인식-8 | C12: 1010 | D12: 정보통신과 | E12: 원동면 | F12: 원동-밀양 경계 | G12: 1 | H12: 2 | J12: 대리 909-10 | K12: 신설 | L12: 2024.03. | M12: 35.445123 | N12: 128.96513
A13: 1 | B13: 차번인식-9 | C13: 1011 | D13: 정보통신과 | E13: 하북면 | F13: 하북-울산 삼동면 경계 | G13: 1 | H13: 2 | J13: 순지리 산 28-5 | K13: 신설 | L13: 2024.03. | M13: 35.497443 | N13: 129.09703
A14: 1 | B14: 차번인식-10 | C14: 1012 | D14: 정보통신과 | E14: 서창동 | F14: 용당동-울산 웅촌면 경계 | G14: 1 | H14: 2 | J14: 용당동 977-1 | K14: 신설 | L14: 2024.03. | M14: 35.431243 | N14: 129.17862
A15: 1 | B15: 차번인식-11 | C15: 1013 | D15: 정보통신과 | E15: 서창동 | F15: 용당동-울산 온양 경계 | G15: 1 | H15: 2 | J15: 용당동 산 17-11 | K15: 신설 | L15: 2024.03. | M15: 35.424443 | N15: 129.1955
A16: 1 | B16: 차번인식-12 | C16: 1014 | D16: 정보통신과 | E16: 동면 | F16: 내송삼거리우측 | G16: 2 | H16: 3 | J16: 양산시 동면 내송리 702-7 | K16: 신설 | L16: 2024.03. | M16: 35.32365 | N16: 129.05806
A17: 1 | B17: 차번인식-13 | C17: 1015 | D17: 정보통신과 | E17: 동면 | F17: 내송삼거리좌측 | G17: 2 | H17: 3 | J17: 양산시 동면 내송리 702-3 | K17: 신설 | L17: 2024.03. | M17: 35.32316 | N17: 129.05831
A18: 1 | B18: 차번인식-14 | C18: 1016 | D18: 정보통신과 | E18: 동면 | F18: 다방7교우측 | G18: 1 | H18: 2 | J18: 양산시 동면 내송리 692-2 | K18: 신설 | L18: 2024.03. | M18: 35.32439 | N18: 129.05908
A19: 1 | B19: 차번인식-15 | C19: 1017 | D19: 정보통신과 | E19: 동면 | F19: 다방8교좌측 | G19: 1 | H19: 2 | J19: 양산시 동면 내송리 696 | K19: 신설 | L19: 2024.03. | M19: 35.32449 | N19: 129.05915
A20: 1 | B20: 차번인식-16 | C20: 1018 | D20: 정보통신과 | E20: 동면 | F20: 자측시설좌측 | G20: 1 | H20: 2 | J20: 양산시 동면 사송리 산23-2 | K20: 신설 | L20: 2025 | M20: 35.30457 | N20: 129.08528
A21: 1 | B21: 차번인식-17 | C21: 1019 | D21: 정보통신과 | E21: 동면 | F21: 자측시설우측 | G21: 2 | H21: 3 | J21: 양산시 동면 사송리 27-7 | K21: 신설 | L21: 2025 | M21: 35.30435 | N21: 129.08506
A22: 1 | B22: 차번인식-18 | C22: 1020 | D22: 정보통신과 | E22: 동면 | F22: 사베소류지(육교부근) | G22: 2 | H22: 3 | J22: 양산시 동면 사송리 80 | K22: 신설 | L22: 2024.03. | M22: 35.29993 | N22: 129.07804
A23: 1 | B23: 차번인식-19 | C23: 1021 | D23: 정보통신과 | E23: 동면 | F23: 양산부산간경계부근 | G23: 2 | H23: 3 | J23: 양산시 동면 사송리 80 | K23: 신설 | L23: 2025 | M23: 35.29936 | N23: 129.08055

Sheet 초등학교_관리번호 재 부여
N1: =SUBTOTAL(3,#REF!) -> #REF!
A3: 개소 | B3: 구분 | C3: 관리번호 | D3: 관리부서 | E3: 행정동 | F3: 카메라명 | G3: 대수 | H3: 설치 지번 | I3: 실제설치장소(주변) | J3: 설치년도 | K3: 변경년도 | L3: 위도 | M3: 경도 | N3: 목적
A4: =SUM(A5:A48) -> 43 | G4: =SUM(G5:G48) -> 260
A5: 1 | B5: 초등학교연계-9 | C5: 2001 | D5: 초등학교 | E5: 양주동 | F5: 신양초등학교 (디지털교체) | G5: 8 | H5: 남부동 553-6 | L5: 35.333826 | M5: 129.02445 | N5: 학교내 설치 CCTV
A6: 1 | B6: 초등학교연계-8 | C6: 2002 | D6: 초등학교 | E6: 양주동 | F6: 삽량초등학교 (디지털교체) | G6: 6 | H6: 남부동 601-3 | L6: 35.332232 | M6: 129.02942 | N6: 학교내 설치 CCTV
A7: 1 | B7: 초등학교연계-12 | C7: 2003 | D7: 초등학교 | E7: 물금읍 | F7: 물금초등학교 (디지털교체) | G7: 2 | H7: 물금읍 가촌리 470 | L7: 35.317126 | M7: 128.99042 | N7: 학교내 설치 CCTV
A8: 1 | B8: 초등학교연계-17 | C8: 2004 | D8: 초등학교 | E8: 물금읍 | F8: 성산초등학교 (디지털교체) | G8: 14 | H8: 물금읍 범어리 2712-6 | L8: 35.330258 | M8: 129.01792 | N8: 학교내 설치 CCTV
A9: 1 | B9: 초등학교연계-16 | C9: 2005 | D9: 초등학교 | E9: 물금읍 | F9: 황산초등학교 (디지털교체) | G9: 8 | H9: 물금읍 범어리 228-2 | L9: 35.331115 | M9: 129.00968 | N9: 학교내 설치 CCTV
A10: 1 | B10: 초등학교연계-13 | C10: 2006 | D10: 초등학교 | E10: 물금읍 | F10: 범어초등학교 (디지털교체) | G10: 4 | H10: 물금읍 범어리 718-3 | L10: 35.331333 | M10: 129.00562 | N10: 학교내 설치 CCTV
A11: 1 | B11: 초등학교연계-15 | C11: 2007 | D11: 초등학교 | E11: 물금읍 | F11: 서남초등학교 (디지털교체) | G11: 4 | H11: 물금읍 범어리 554 | J11: 2015 | L11: 35.32856 | M11: 128.99908 | N11: 학교내 설치 CCTV
A12: 1 | B12: 초등학교연계-19 | C12: 2008 | D12: 초등학교 | E12: 원동면 | F12: 화제초등학교 (디지털교체) | G12: 6 | H12: 원동면 화제리 1296-2 | J12: 2016 | K12: 2023.06 | L12: 35.351311 | M12: 128.97897 | N12: 학교내 설치 CCTV
A13: 1 | B13: 초등학교연계-18 | C13: 2009 | D13: 초등학교 | E13: 원동면 | F13: 원동초등학교 | G13: 4 | H13: 원동면 원리 951 | L13: 35.364207 | M13: 128.92235 | N13: 학교내 설치 CCTV
A14: 1 | B14: 초등학교연계-6 | C14: 2010 | D14: 초등학교 | E14: 강서동 | F14: 어곡초등학교 (디지털교체) | G14: 7 | H14: 어곡동 150 → 어곡동 11 (이동) | J14: 2016 | L14: 35.374969 | M14: 129.02824 | N14: 학교내 설치 CCTV
A15: 1 | B15: 초등학교연계-7 | C15: 2011 | D15: 초등학교 | E15: 양주동 | F15: 중부초등학교 (디지털교체) | G15: 7 | H15: 중부동 696-2 | L15: 35.336818 | M15: 129.03316 | N15: 학교내 설치 CCTV
A16: 1 | B16: 초등학교연계-2 | C16: 2012 | D16: 초등학교 | E16: 양주동 | F16: 양주초등학교 (디지털4) | G16: 7 | H16: 중부동 422-3 | J16: 2017(디지털) | L16: 35.342587 | M16: 129.03186 | N16: 학교내 설치 CCTV
A17: 1 | B17: 초등학교연계-1 | C17: 2013 | D17: 초등학교 | E17: 중앙동 | F17: 양산초등학교 | G17: 6 | H17: 북부동 269 | J17: 2011 | L17: 35.345284 | M17: 129.04359 | N17: 학교내 설치 CCTV
A18: 1 | B18: 초등학교연계-3 | C18: 2014 | D18: 초등학교 | E18: 삼성동 | F18: 신기초등학교 (디지털교체) | G18: 12 | H18: 신기동 511-1 | L18: 35.352206 | M18: 129.04054 | N18: 학교내 설치 CCTV
A19: 1 | B19: 초등학교연계-5 | C19: 2015 | D19: 초등학교 | E19: 삼성동 | F19: 북정초등학교 (디지털교체) | G19: 4 | H19: 북정동 884-1 | L19: 35.364421 | M19: 129.04704 | N19: 학교내 설치 CCTV
A20: 1 | B20: 초등학교연계-4 | C20: 2016 | D20: 초등학교 | E20: 삼성동 | F20: 삼성초등학교 (디지털교체) | G20: 6 | H20: 북정동 382-1 | L20: 35.364421 | M20: 129.04704 | N20: 학교내 설치 CCTV
A21: 1 | B21: 초등학교연계-21 | C21: 2017 | D21: 초등학교 | E21: 상북면 | F21: 소토초등학교 (디지털교체) | G21: 5 | H21: 상북면 소토리 651 | J21: 2015 | L21: 35.379596 | M21: 129.05334 | N21: 학교내 설치 CCTV
A22: 1 | B22: 초등학교연계-20 | C22: 2018 | D22: 초등학교 | E22: 상북면 | F22: 상북초등학교 (디지털교체) | G22: 8 | H22: 상북면 석계리 122 | L22: 35.416338 | M22: 129.0604 | N22: 학교내 설치 CCTV
A23: 1 | B23: 초등학교연계-22 | C23: 2019 | D23: 초등학교 | E23: 상북면 | F23: 좌삼초등학교 (디지털교체) | G23: 2 | H23: 상북면 좌삼리 493 | J23: 2015 | L23: 35.440914 | M23: 129.04392 | N23: 학교내 설치 CCTV
A24: 1 | B24: 초등학교연계-24 | C24: 2020 | D24: 초등학교 | E24: 하북면 | F24: 용연초등학교 | G24: 4 | H24: 하북면 백록리 1245 | L24: 35.449636 | M24: 129.07517 | N24: 학교내 설치 CCTV
A25: 1 | B25: 초등학교연계-23 | C25: 2021 | D25: 초등학교 | E25: 하북면 | F25: 하북초등학교 (디지털교체) | G25: 4 | H25: 하북면 순지리 702 | L25: 35.490192 | M25: 129.0879 | N25: 학교내 설치 CCTV
A26: 1 | B26: 초등학교연계-10 | C26: 2022 | D26: 초등학교 | E26: 동면 | F26: 영천초등학교 | G26: 3 | H26: 동면 여락리 18 | I26: 여락리 30 | J26: 2015 | L26: 35.31127 | M26: 129.11043 | N26: 학교내 설치 CCTV
A27: 1 | B27: 초등학교연계-25 | C27: 2023 | D27: 초등학교 | E27: 서창동 | F27: 웅상초등학교 (디지털교체) | G27: 5 | H27: 명동 986 | J27: 2015 | L27: 35.398831 | M27: 129.16437 | N27: 학교내 설치 CCTV
A28: 1 | B28: 초등학교연계-26 | C28: 2024 | D28: 초등학교 | E28: 덕계동 | F28: 덕계초등학교 | G28: 5 | H28: 덕계동 718-4 | L28: 35.375756 | M28: 129.15323 | N28: 학교내 설치 CCTV
A29: 1 | B29: 초등학교연계-31 | C29: 2025 | D29: 초등학교 | E29: 평산동 | F29: 천성초등학교 | G29: 5 | H29: 평산동 350 | L29: 35.379596 | M29: 129.14435 | N29: 학교내 설치 CCTV
A30: 1 | B30: 초등학교연계-37 | C30: 2026 | D30: 초등학교 | E30: 동면 | F30: 금오초중학교 | G30: 7 | H30: 동면 석산리 1448-1 | J30: 2020 | L30: 35.322088 | M30: 129.02773 | N30: 학교내 설치 CCTV
A31: 1 | B31: 초등학교연계-27 | C31: 2027 | D31: 초등학교 | E31: 평산동 | F31: 평산초등학교 (디지털교체) | G31: 7 | H31: 평산동 40-3 | L31: 35.386827 | M31: 129.15391 | N31: 학교내 설치 CCTV
A32: 1 | B32: 초등학교연계-32 | C32: 2028 | D32: 초등학교 | E32: 소주동 | F32: 백동초등학교(디지털교체) | G32: 6 | H32: 소주동 669 | L32: 35.405591 | M32: 129.15344 | N32: 학교내 설치 CCTV
A33: 1 | B33: 초등학교연계-30 | C33: 2029 | D33: 초등학교 | E33: 서창동 | F33: 대운초등학교 | G33: 7 | H33: 삼호동 886-2 | L33: 35.408994 | M33: 129.17363 | N33: 학교내 설치 CCTV
A34: 1 | B34: 초등학교연계-29 | C34: 2030 | D34: 초등학교 | E34: 서창동 | F34: 서창초등학교 (디지털교체) | G34: 8 | H34: 삼호동 623 | J34: 2015 | L34: 35.417782 | M34: 129.1718 | N34: 학교내 설치 CCTV
A35: 1 | B35: 초등학교연계-11 | C35: 2031 | D35: 초등학교 | E35: 동면 | F35: 동산초등학교 (디지털교체) | G35: 5 | H35: 동면 금산리 783 | L35: 35.303695 | M35: 129.02629 | N35: 학교내 설치 CCTV
A36: 1 | B36: 초등학교연계-33 | C36: 2032 | D36: 초등학교 | E36: 동면 | F36: 석산초등학교 | G36: 7 | H36: 동면 석산리 1448-8 | L36: 35.32196 | M36: 129.02724 | N36: 학교내 설치 CCTV
A37: 1 | B37: 초등학교연계-28 | C37: 2033 | D37: 초등학교 | E37: 평산동 | F37: 신명초등학교 (디지털교체) | G37: 4 | H37: 평산동 570-49 | L37: 35.388886 | M37: 129.14213 | N37: 학교내 설치 CCTV
A38: 1 | B38: 초등학교연계-34 | C38: 2034 | D38: 초등학교 | E38: 물금읍 | F38: 증산초등학교 | G38: 6 | H38: 물금읍 범어리 2785-1 | J38: 2017 | L38: 35.315567 | M38: 129.00706 | N38: 학교내 설치 CCTV
A39: 1 | B39: 초등학교연계-35 | C39: 2035 | D39: 초등학교 | E39: 물금읍 | F39: 신주초등학교 | G39: 6 | H39: 물금읍 범어리 2673-1 | I39: 증산리 957-5 | J39: 2017 | L39: 35.337149 | M39: 129.01962 | N39: 학교내 설치 CCTV
A40: 1 | B40: 초등학교연계-36 | C40: 2036 | D40: 초등학교 | E40: 물금읍 | F40: 가남초등학교 | G40: 5 | H40: 물금읍 가촌리 1277-5 | L40: 35.311978 | M40: 128.99818 | N40: 학교내 설치 CCTV
A41: 1 | B41: 초등학교연계-14 | C41: 2037 | D41: 초등학교 | E41: 물금읍 | F41: 오봉초등학교 (디지털교체) | G41: 8 | H41: 물금읍 범어리 503 | L41: 35.334225 | M41: 129.00419 | N41: 학교내 설치 CCTV
...

Sheet 교통상황수집
A3: 개소 | B3: 구분 | C3: 관리번호 | D3: 관리부서 | E3: 행정동 | F3: 카메라명 | G3: 대수 | H3: 수정주소(도로점용) | I3: 설치 지번 | J3: 실제설치장소(주변) | K3: 설치년도 | L3: 위도 | M3: 경도 | N3: 설치목적
A4: =SUM(A5:A94) -> 46 | G4: =SUM(G5:G94) -> 58
A5: 1 | B5: 교통상황수집-1 | C5: 9001 | D5: 정보통계과 | E5: 하북면 | F5: CCTV01_공원묘지입구 | G5: 1 | H5: 하북면 답곡리 1109-1 | I5: 하북면 답곡리 1109-1 | J5: 답곡리 702-1(우리꽃집슈퍼 앞 삼각지) | K5: 2013 | L5: 35.475251 | M5: 129.08716 | N5: 교통정보수집
A6: 1 | B6: 교통상황수집-2 | C6: 9002 | D6: 정보통계과 | E6: 상북면 | F6: CCTV02_반회삼거리 | G6: 1 | H6: 상북면 석계리 529-6 | I6: 상북면 석계리 529-6 | J6: 상북면 석계리 529-1(더타이어샵 맞은편) | K6: 2013 | L6: 35.41229 | M6: 129.05632 | N6: 교통정보수집
A7: 1 | B7: 교통상황수집-3 | C7: 9003 | D7: 정보통계과 | E7: 물금읍 | F7: CCTV03_범어정수장입구 | G7: 1 | H7: 물금읍 범어리 2763 | I7: 물금읍 범어리 2763 | J7: 물금읍 범어리 2763 (버스정류장(범어정수장/2622/경민아파트방면)에서 양산소방서 방향 25m 떨어진 곳 설치, 횡단보도 바로 옆) | K7: 2013 | L7: 35.335905 | M7: 129.01282 | N7: 교통정보수집
A8: 1 | B8: 교통상황수집-4 | C8: 9004 | D8: 정보통계과 | E8: 동면 | F8: CCTV04_창기마을인근 | G8: 1 | H8: 동면 법기리 961-4 | I8: 동면 법기리 961-4 | J8: 동면 법기리 732(한솔원예조경 맞은편) | K8: 2013 | L8: 35.331417 | M8: 129.12188 | N8: 교통정보수집
A9: 1 | B9: 교통상황수집-5 | C9: 9005 | D9: 정보통계과 | E9: 동면 | F9: CCTV05_남양산 IC | G9: 1 | H9: 동면 석산리 640-28 | I9: 동면 석산리 640-28 | J9: 동면 석산리 640-28(남양산IC 진입로 지나서 130m 떨어진 곳에 설치) | K9: 2013 | L9: 35.322799 | M9: 129.03008 | N9: 교통정보수집
A10: 1 | B10: 교통상황수집-6 | C10: 9006 | D10: 정보통계과 | E10: 동면 | F10: CCTV06_호포고가교 | G10: 1 | H10: 동면 가산리 986 -1 | I10: 동면 가산리 986 -1 | J10: 동면 가산리 986 -1(호포고갸교 밑 삼각지) | K10: 2013 | L10: 35.288121 | M10: 129.01495 | N10: 교통정보수집
A11: 1 | B11: 교통상황수집-7 | C11: 9007 | D11: 정보통계과 | E11: 동면 | F11: CCTV07_동산초교앞 삼거리 | G11: 1 | H11: 동면 금산리 1495 | I11: 동면 금산리 1495 | J11: 동면 금산리 1495(버스정류장(금산휴먼시아/2819/가산마을방면)바로 옆, CU편의점 맞은편) | K11: 2013 | L11: 35.303861 | M11: 129.02464 | N11: 교통정보수집
A12: 1 | B12: 교통상황수집-8 | C12: 9008 | D12: 정보통계과 | E12: 삼성동 | F12: CCTV08_산막공단입구 삼거리 | G12: 1 | H12: 북정동 210-33 | I12: 북정동 210-33 | J12: 북정동 210-46(부산계량사에서 하북방향으로 50m 떨어진 곳에 설치) | K12: 2013 | L12: 35.371045 | M12: 129.04493 | N12: 교통정보수집
A13: 1 | B13: 교통상황수집-9 | C13: 9009 | D13: 정보통계과 | E13: 삼성동 | F13: CCTV09_새롬성원아파트 사거리 | G13: 1 | H13: 북정동 738-5 | I13: 북정동 738-5 | J13: 북정동 891-2(글라스 스토리 안경원 북정점 앞 횡단보도 건너 삼각지) | K13: 2013 | L13: 35.358794 | M13: 129.04486 | N13: 교통정보수집
A14: 1 | B14: 교통상황수집-10 | C14: 9010 | D14: 정보통계과 | E14: 강서동 | F14: CCTV10_강서치안센터 삼거리 | G14: 1 | H14: 유산동 167-6 | I14: 유산동 167-6 | J14: 유산동 159-8(강서파출소 기준에서 상북방향으로 2시방향에 위치) | K14: 2013 | L14: 35.358153 | M14: 129.0357 | N14: 교통정보수집
A15: 1 | B15: 교통상황수집-11 | C15: 9011 | D15: 정보통계과 | E15: 양주동 | F15: CCTV11_종합운동장 사거리 | G15: 1 | H15: 북부동536-2 | I15: 북부동536-2 | J15: 북부동 536-2(종합 운동장 차량 진입로 맞은편 횡단보도) | K15: 2013 | L15: 35.343495 | M15: 129.03372 | N15: 교통정보수집
A16: 1 | B16: 교통상황수집-12 | C16: 9012 | D16: 정보통계과 | E16: 물금읍 | F16: CCTV12_협성강변타운 삼거리 | G16: 1 | H16: 물금읍 범어리 2808 | I16: 물금읍 범어리 2808 | J16: 물금읍 범어리 2763(워터파크에서 강서동방향으로 떨어진 삼각지 / 버스정류장(워터파크/5174/향교가있는교동마을 방면)에서 강서동 방향으로 300m 떨어진 삼각지 | K16: 2013 | L16: 35.340767 | M16: 129.02447 | N16: 교통정보수집
... A32: 1 | B32: 교통상황수집-28 | C32: 9028 | D32: 정보통계과 | E32: 양주동 | F32: CCTV28_신도시주유소사거리 | G32: 1 | H32: 중부동 698-16 | I32: 중부동 698-16 | J32: 중부동 693-5(s-oil 주유소 앞 횡단보도) | K32: 2013 | L32: 35.334938 | M32: 129.02884 | N32: 교통정보수집
A33: 9008RSE | B33: 교통상황수집-29 | C33: 9029 | D33: 정보통계과 | E33: 삼성동 | F33: CCTV29_산막공단북정교 | G33: 1 | H33: 북정동 210-33 | I33: 북정동 210-33 | J33: 북정동 210-46(부산계량사에서 하북방향으로 50m 떨어진 곳에 설치) | K33: 2015.5. | L33: 35.371045 | M33: 129.04493 | N33: 교통정보수집
A34: 9022RSE | B34: 교통상황수집-30 | C34: 9030 | D34: 정보통계과 | E34: 덕계동 | F34: CCTV30_덕계사거리1 | G34: 1 | H34: 덕계동 725 | I34: 덕계동 725 | J34: 덕계동 724-4(날마다대박나는집 앞 황단보도) | K34: 2015.5. | L34: 35.373649 | M34: 129.15279 | N34: 교통정보수집
A35: 9023RSE | B35: 교통상황수집-31 | C35: 9031 | D35: 정보통계과 | E35: 서창동 | F35: CCTV31_삼호사거리1 | G35: 1 | H35: 삼호동 663-5 | I35: 삼호동 665-11 | J35: 삼호동 663-5(삼호사거리 영산대 방향 횡단보도) | K35: 2015.5. | L35: 35.415654 | M35: 129.16841 | N35: 교통정보수집
A36: 9024RSE | B36: 교통상황수집-32 | C36: 9032 | D36: 정보통계과 | E36: 서창동 | F36: CCTV32_용당마을1 | G36: 1 | H36: 용당동 566-1 | I36: 용당동 566-1 | J36: 용당동 565-1(태림공인중개사 앞 사거리) | K36: 2015.5. | L36: 35.427689 | M36: 129.18354 | N36: 교통정보수집
A37: 1 | B37: 교통상황수집-33 | C37: 9033 | D37: 정보통계과 | E37: 상북면 | F37: CCTV33_고려제강앞 삼거리 | G37: 1 | H37: 소토리 767-2 | I37: 상북면 소토리 912-2 | J37: 상북면 소토리 912-2(고려제강 입구 좌측) | K37: 2015.5. | L37: 35.386294 | M37: 129.05147 | N37: 교통정보수집
A38: 9016RSE | B38: 교통상황수집-34 | C38: 9034 | D38: 정보통계과 | E38: 물금읍 | F38: CCTV34_물금읍사무소 앞 | G38: 1 | H38: 물금리 898-1 | I38: 물금읍 물금리 401-51 | J38: 물금리411-10(쌀엔개사료 맞은편, 횡단보도 바로 옆) | K38: 2015.5. | L38: 35.310187 | M38: 128.98659 | N38: 교통정보수집
A39: 9013RSE | B39: 교통상황수집-35 | C39: 9035 | D39: 정보통계과 | E39: 강서동 | F39: CCTV35_어곡사거리 1 | G39: 1 | H39: 어곡동 175-4 | I39: 어곡동 175-4 | J39: 어곡동 158(진흥기계공업사에서 어곡터널 방향 40m 떨어진 삼각지) | K39: 2015.5. | L39: 35.373707 | M39: 129.0274 | N39: 교통정보수집
A40: 1 | B40: 교통상황수집-36 | C40: 9036 | D40: 정보통계과 | E40: 서창동 | F40: CCTV36_서창북부 삼거리 | G40: 1 | H40: 삼호동 334-4 | I40: 삼호동 334-4 | J40: 삼호동 201(신라해장국 맞은 편 공원 쪽) | K40: 2015.5. | L40: 35.420672 | M40: 129.17701 | N40: 교통정보수집
A41: 1 | B41: 교통상황수집-37 | C41: 9037 | D41: 정보통계과 | E41: 양주동 | F41: CCTV37_북부사 거리 | G41: 1 | H41: 북부동 158-8 | I41: 북부동 158-8 | J41: 북부동 158-8(전자랜드 맞은 편 운동장쪽 횡단보도) | K41: 2015.5. | L41: 35.348968 | M41: 129.03624 | N41: 교통정보수집
A42: 1 | B42: 교통상황수집-38 | C42: 9038 | D42: 정보통계과 | E42: 하북면 | F42: CCTV38_내원사입구 삼거리 | G42: 1 | H42: 하북면 용연리 1137-17 | I42: 하북면 용연리 1137-17 | J42: 용연리 818-1(분체계량기술연구소 맞은 편) | K42: 2015.5. | L42: 35.439896 | M42: 129.07181 | N42: 교통정보수집
A43: 9018RSE | B43: 교통상황수집-39 | C43: 9039 | D43: 정보통계과 | E43: 물금읍 | F43: CCTV_39_범어지하차도 사거리 | G43: 1 | H43: 범어리 2763 | I43: 물금읍 범어리 386-2 | J43: 범어리 385-28(범어자전거할인마트 바로 앞) | K43: 2015.11. | L43: 35.330468 | M43: 129.00639 | N43: 교통정보수집
A44: 9010RSE | B44: 교통상황수집-40 | C44: 9040 | D44: 정보통계과 | E44: 강서동 | F44: CCTV_40_강서치안센터 삼거리 | G44: 1 | H44: 유산동 167-6 | I44: 유산동 168-37 | J44: 유산동 159-8(강서파출소 기준에서 상북방향으로 2시방향에 위치) | K44: 2015.11. | L44: 35.358153 | M44: 129.0357 | N44: 교통정보수집
A45: 9011RSE | B45: 교통상황수집-41 | C45: 9041 | D45: 정보통계과 | E45: 중앙동 | F45: CCTV_41_종합운동장 사거리 | G45: 1 | H45: 북부동536-2 | I45: 북부동 529-13 | J45: 북부동 536-2(종합 운동장 차량 진입로 맞은편 횡단보도) | K45: 2015.11. | L45: 35.343495 | M45: 129.03372 | N45: 교통정보수집
A46: 1 | B46: 교통상황수집-42 | C46: 9042 | D46: 정보통계과 | E46: 양주동 | F46: CCTV_42_양산역앞 삼거리 | G46: 1 | H46: 중부동 704 | I46: 중부동 704 | J46: 중부동 685-8(양산역 1번 출구 쪽 횡단보도) | K46: 2015.11. | L46: 35.337845 | M46: 129.02608 | N46: 교통정보수집
A47: 1 | B47: 교통상황수집-43 | C47: 9043 | D47: 정보통계과 | E47: 양주동 | F47: CCTV_43_양주교밑 사거리 | G47: 1 | H47: 남부동 884 | I47: 남부동 884 | J47: 남부동 608-1 (상록경남아너스빌 104동앞) | K47: 2015.11. | L47: 35.329667 | M47: 129.02313 | N47: 교통정보수집
A48: 1 | B48: 교통상황수집-44 | C48: 9044 | D48: 정보통계과 | E48: 중앙동 | F48: CCTV_44_다방교 사거리 | G48: 1 | H48: 다방동 502-7 | I48: 다방동 502-7 | J48: 다방동 502-7(더타이어샵 사거리 다방교 방향 버스정류장 옆) | K48: 2015.11. | L48: 35.331336 | M48: 129.03954 | N48: 교통정보수집
A49: 9015RSE | B49: 교통상황수집-45 | C49: 9045 | D49: 정보통계과 | E49: 양주동 | F49: CCTV_45_석산교 사거리 | G49: 1 | H49: 남부동 425-32 | I49: 남부동 425-32 | J49: 남부동 858-11(석산교 지나서 남부동 방면으로 70m 떨어진 삼각지) | K49: 2015.11. | L49: 35.329884 | M49: 129.03474 | N49: 교통정보수집
A50: 1 | B50: 교통상황수집-46 | C50: 9046 | D50: 정보통계과 | E50: 동면 | F50: CCTV_46_석산교차로 | G50: 1 | H50: 동면 석산리 1493 | I50: 동면 석산리 1493 | J50: 석산리 1477-7(석산교차로 호포방향 더프라임휘트니스 옆) | K50: 2015.11. | L50: 35.315423 | M50: 129.02747 | N50: 교통정보수집
A51: 9007RSE | B51: 교통상황수집-47 | C51: 9047 | D51: 정보통계과 | E51: 동면 | F51: CCTV_47_동산초앞 사거리 | G51: 1 | H51: 동면 금산리 1495 | I51: 동면 금산리 774 | J51: 동면 금산리 1495(버스정류장(금산휴먼시아/2819/가산마을방면)바로 옆, CU편의점 맞은편) | K51: 2015.11. | L51: 35.303861 | M51: 129.02464 | N51: 교통정보수집
A52: 9019RSE | B52: 교통상황수집-48 | C52: 9048 | D52: 정보통계과 | E52: 동면 | F52: CCTV_48_물금IC 삼거리 | G52: 1 | H52: 동면 금산리 1160-8 | I52: 동면 금산리 1175-3 | J52: 증산리 1237-8(물금TG 진입로에서 40m 떨어진 곳에 설치/진입로 건너편) | K52: 2015.11. | L52: 35.308101 | M52: 129.01722 | N52: 교통정보수집
A53: 9003RSE | B53: 교통상황수집-49 | C53: 9049 | D53: 정보통계과 | E53: 물금읍 | F53: CCTV_49_범어정수장앞 삼거리 | G53: 1 | H53: 물금읍 범어리 2763 | I53: 물금읍 범어리 2763 | J53: 물금읍 범어리 2763 (버스정류장(범어정수장/2622/경민아파트방면)에서 양산소방서 방향 25m 떨어진 곳 설치, 횡단보도 바로 옆) | K53: 2015.11. | L53: 35.335905 | M53: 129.01282 | N53: 교통정보수집
A54: 1 | B54: 교통상황수집-50 | C54: 9050 | D54: 정보통계과 | E54: 물금읍 | F54: CCTV_50_부산대 캠퍼스역 삼거리 | G54: 1 | H54: 범어리 2762-7 | I54: 물금읍 범어리 2710-5 | J54: 범어리 2762-7(에이원메트로상가 맞은편 공원 쪽) | K54: 2015.11. | L54: 35.315572 | M54: 129.01254 | N54: 교통정보수집
A55: 1 | B55: 교통상황수집-51 | C55: 9051 | D55: 정보통계과 | E55: 물금읍 | F55: CCTV_51_양산부산대학교병원삼거리(황전아파트) | G55: 1 | H55: 물금읍 범어리 2833 | I55: 물금읍 범어리 2833 | J55: 범어리 551-2(현대약국 앞) | K55: 2017 | L55: 35.325884 | M55: 129.00056 | N55: 교통정보수집
A56: 1 | B56: 교통상황수집-52 | C56: 9052 | D56: 정보통계과 | E56: 물금읍 | F56: CCTV_52_남평삼거리 | G56: 1 | H56: 물금읍 증산리 796-5 | I56: 물금읍 증산리 796-5 | J56: 물금읍 증산리 796-5(하늘완구 맞은편) | K56: 2013 | L56: 35.295595 | M56: 129.00299 | N56: 교통정보수집
A57: 1 | B57: 교통상황수집-53 | C57: 9053 | D57: 정보통계과 | E57: 하북면 | F57: CCTV_53_통도사입구 | G57: 1 | H57: 하북면 순지리 174 | I57: 하북면 순지리 174-1 | J57: 순지리 828-2(이순남순두부정식 맞은 편) | K57: 2013 | L57: 35.493843 | M57: 129.09036 | N57: 교통정보수집
...

Sheet VDS
P1: =SUBTOTAL(3,#REF!) -> #REF!
A3: 개소 | B3: 구분 | C3: 관리번호 | D3: 관리부서 | E3: 행정동 | F3: 카메라명 | G3: 대수 | H3: 수정주소(도로점용) | I3: 설치 지번 | J3: 실제설치장소(주변) | K3: 설치년도 | L3: 변경년도 | M3: 화소수 | N3: 위도 | O3: 경도 | P3: 목적
A4: =SUM(A5:A95) -> 9 | G4: =SUM(G5:G95) -> 9
A5: 1 | B5: VDS | C5: 9901 | D5: 정보통계과 | E5: 동면 | F5: 사송 | G5: 1 | K5: 2024
A6: 1 | B6: VDS | C6: 9902 | D6: 정보통계과 | E6: 동면 | F6: 사송 | G6: 1 | K6: 2024
A7: 1 | B7: VDS | C7: 9903 | D7: 정보통계과 | E7: 동면 | F7: 사송 | G7: 1 | K7: 2024
A8: 1 | B8: VDS | C8: 9904 | D8: 정보통계과 | E8: 동면 | F8: 사송 | G8: 1 | K8: 2024
A9: 1 | B9: VDS | C9: 9905 | D9: 정보통계과 | E9: 평산동 | G9: 1 | H9: 양산시 평산동 31-49 | I9: 양산시 평산동 31-49 | J9: 양산시 평산동 31-49 | K9: 2024.08 | P9: 교통
A10: 1 | B10: VDS | C10: 9906 | D10: 정보통계과 | E10: 상북면 | G10: 1 | H10: 양산시 상북면 소토리 1214 | I10: 양산시 상북면 소토리 1214 | J10: 양산시 상북면 소토리 1214 | K10: 2024.08 | P10: 교통
A11: 1 | B11: VDS | C11: 9907 | D11: 정보통계과 | E11: 양주동 | G11: 1 | H11: 양산시 남부동 615 | I11: 양산시 남부동 615 | J11: 양산시 남부동 615 | K11: 2024.08 | P11: 교통
A12: 1 | B12: VDS | C12: 9908 | D12: 정보통계과 | E12: 물금읍 | G12: 1 | H12: 양산시 물금읍 범어리 2762-5 | I12: 양산시 물금읍 범어리 2762-5 | J12: 양산시 물금읍 범어리 2762-5 | K12: 2024.08 | P12: 교통
A13: 1 | B13: VDS | C13: 9907 | D13: 정보통계과 | E13: 물금읍 | G13: 1 | H13: 양산시 물금읍 증산리 1732 | I13: 양산시 물금읍 증산리 1732 | J13: 양산시 물금읍 증산리 1732 | K13: 2024.08 | P13: 교통

Sheet 재난재해
A3: 개소 | B3: 구분 | C3: 관리번호 | D3: 관리부서 | E3: 행정동 | F3: 카메라명 | G3: 대수 | H3: 설치 지번 | I3: 실제설치장소(주변) | J3: 설치년도 | K3: 변경년도 | L3: 위도 | M3: 경도 | N3: 설치목적
A4: =SUM(A5:A74) -> 53 | G4: =SUM(G5:G74) -> 78
A5: 1 | B5: 재난재해-1 | C5: 3001 | D5: 하천과 | E5: 물금읍 | F5: 낙동강친수시설-1 | G5: 3 | H5: 물금읍 물금리 173 | J5: 2013 | L5: 35.302556 | M5: 128.99019 | N5: 재난재해,시설물관리
A6: 1 | B6: 재난재해-2 | C6: 3002 | D6: 하천과 | E6: 물금읍 | F6: 낙동강친수시설-2 | G6: 2 | H6: 물금읍 물금리 657 | J6: 2013 | L6: 35.310572 | M6: 128.97763 | N6: 재난재해,시설물관리
A7: 1 | B7: 재난재해-3 | C7: 3003 | D7: 하천과 | E7: 물금읍 | F7: 낙동강친수시설-3 | G7: 3 | H7: 물금읍 증산리 212 | J7: 2013 | L7: 35.287474 | M7: 129.01075 | N7: 재난재해,시설물관리
A8: 1 | B8: 재난재해-4 | C8: 3004 | D8: 하천과 | E8: 물금읍 | F8: 낙동강친수시설-4 | G8: 2 | H8: 물금읍 증산리 349 | J8: 2013 | L8: 35.291496 | M8: 129.00233 | N8: 재난재해,시설물관리
A9: 1 | B9: 재난재해-5 | C9: 3005 | D9: 하천과 | E9: 원동면 | F9: 낙동강친수시설-5 | G9: 3 | H9: 원동면 서룡리 586 | J9: 2013 | L9: 35.336283 | M9: 128.96002 | N9: 재난재해,시설물관리
A10: 1 | B10: 재난재해-6 | C10: 3006 | D10: 하천과 | E10: 원동면 | F10: 낙동강친수시설-6 | G10: 3 | H10: 원동면 화제리 2879-3 | J10: 2013 | L10: 35.33242 | M10: 128.97088 | N10: 재난재해,시설물관리
A11: 1 | B11: 재난재해-7 | C11: 3007 | D11: 하천과 | E11: 원동면 | F11: 낙동강친수시설-7 | G11: 3 | H11: 원동면 용당리 560 | J11: 2013 | L11: 35.369222 | M11: 128.90395 | N11: 재난재해,시설물관리
A12: 1 | B12: 재난재해-8 | C12: 3008 | D12: 하천과 | E12: 원동면 | F12: 낙동강친수시설-8 | G12: 3 | H12: 원동면 용당리 1314 | J12: 2013 | L12: 35.368757 | M12: 128.88831 | N12: 재난재해,시설물관리
A13: 1 | B13: 재난재해-9 | C13: 3009 | D13: 하천과 | E13: 원동면 | F13: 낙동강친수시설-9 | G13: 2 | H13: 원동면 용당리 1468 | J13: 2013 | L13: 35.377435 | M13: 128.87771 | N13: 재난재해,시설물관리
A14: 1 | B14: 재난재해-10 | C14: 3010 | D14: 하천과 | E14: 중앙동 | F14: 구름다리-1 | G14: 4 | H14: 북부동 642 | I14: 종합운동장-춘추공원 | J14: 2014 | L14: 35.345998 | M14: 129.032051 | N14: 재난재해,시설물관리
A15: 1 | B15: 재난재해-11 | C15: 3011 | D15: 하천과 | E15: 중앙동 | F15: 구름다리-2 | G15: 1 | H15: 북부동 642 | I15: 종합운동장-춘추공원 | J15: 2014 | L15: 35.345817 | M15: 129.032051 | N15: 재난재해,시설물관리
A16: 1 | B16: 재난재해-12 | C16: 3012 | D16: 하천과 | E16: 원동면 | F16: 낙동강 포토존 | G16: 1 | H16: 물금읍 증산리 1088-1 | I16: 3003 에 등록 | J16: 2013 | L16: 35.291732 | M16: 129.00055 | N16: 재난재해,시설물관리
A17: 1 | B17: 재난재해-13 | C17: 3013 | D17: 시민안전과 | E17: 상북면 | F17: 양산천(소토한우) | G17: 1 | H17: 소토리 1287-34 | L17: 35.397295 | M17: 129.05121 | N17: 재난재해,시설물관리
A18: 1 | B18: 재난재해-14 | C18: 3014 | D18: 시민안전과 | E18: 동면 | F18: 법기 | G18: 1 | H18: 법기리 246-4 | L18: 35.346413 | M18: 129.10939 | N18: 재난재해,시설물관리
A19: 1 | B19: 재난재해-15 | C19: 3015 | D19: 시민안전과 | E19: 평산동 | F19: 무지개(무지개폭포) | G19: 1 | H19: 평산동 1088 | L19: 35.381718 | M19: 129.12323 | N19: 재난재해,시설물관리
A20: 1 | B20: 재난재해-16 | C20: 3016 | D20: 시민안전과 | E20: 원동면 | F20: 대리(포시즌펜션) | G20: 1 | H20: 대리 968-3 | L20: 35.452419 | M20: 128.96401 | N20: 재난재해,시설물관리
A21: 1 | B21: 재난재해-17 | C21: 3017 | D21: 시민안전과 | E21: 원동면 | F21: 선리(느티나무펜션) | G21: 1 | H21: 선리 2163 | L21: 35.498546 | M21: 128.99247 | N21: 재난재해,시설물관리
A22: 1 | B22: 재난재해-18 | C22: 3018 | D22: 시민안전과 | E22: 원동면 | F22: 낙동강(순명원앞) | G22: 1 | H22: 원리 산106-7도 | L22: 35.358468 | M22: 128.92585 | N22: 재난재해,시설물관리
A23: 1 | B23: 재난재해-19 | C23: 3019 | D23: 시민안전과 | E23: 원동면 | F23: 어영(포시즌) | G23: 1 | H23: 영포리 산 230-3 | L23: 35.416751 | M23: 128.93563 | N23: 재난재해,시설물관리
A24: 1 | B24: 재난재해-20 | C24: 3020 | D24: 시민안전과 | E24: 하북면 | F24: 내원사(주차장입구) | G24: 1 | H24: 용연리 278-2 | L24: 35.444591 | M24: 129.09314 | N24: 재난재해,시설물관리
A25: 1 | B25: 재난재해-21 | C25: 3021 | D25: 시민안전과 | E25: 소주동 | F25: 명곡소류지 | G25: 1 | H25: 명동 산 21 | L25: 35.399525 | M25: 129.17547 | N25: 재난재해,시설물관리
A26: 1 | B26: 재난재해-22 | C26: 3022 | D26: 시민안전과 | E26: 소주동 | F26: 소주동 천성리버타운 | G26: 1 | H26: 명동 1033-2 | L26: 35.407772 | M26: 129.16049 | N26: 재난재해,시설물관리
A27: 1 | B27: 재난재해-23 | C27: 3023 | D27: 시민안전과 | E27: 서창동 | F27: 용당동 명문가구 | G27: 1 | H27: 용당동 390-9 | L27: 35.433569 | M27: 129.18919 | N27: 재난재해,시설물관리
A28: 1 | B28: 재난재해-24 | C28: 3024 | D28: 시민안전과 | E28: 원동면 | F28: 적설계 에덴벨리 | G28: 1 | H28: 어곡동2091-13 | L28: 35.421691 | M28: 128.98976 | N28: 재난재해,시설물관리
A29: 1 | B29: 재난재해-25 | C29: 3025 | D29: 시민안전과 | E29: 원동면 | F29: 적설계 원동 늘밭마을 | G29: 1 | H29: 원동면 내포리 1674 | L29: 35.408797 | M29: 128.96801 | N29: 재난재해,시설물관리
A30: 1 | B30: 재난재해-26 | C30: 3026 | D30: 시민안전과 | E30: 원동면 | F30: 적설계 원동 내포리 | G30: 1 | H30: 원동면 대리 966-2 | L30: 35.451996 | M30: 128.9645 | N30: 재난재해,시설물관리
A31: 1 | B31: 재난재해-27 | C31: 3027 | D31: 도로정비과 | E31: 물금읍 | F31: 물금펌프장외부 | G31: 1
A32: 1 | B32: 재난재해-28 | C32: 3028 | D32: 도로정비과 | E32: 물금읍 | F32: ICD차도 | G32: 1
A33: 1 | B33: 재난재해-29 | C33: 3029 | D33: 도로정비과 | E33: 물금읍 | F33: 32채널 NVR_1 | G33: 1
A34: 1 | B34: 재난재해-30 | C34: 3030 | D34: 도로정비과 | E34: 물금읍 | F34: 32채널 NVR_3 | G34: 1
A35: 1 | B35: 재난재해-31 | C35: 3031 | D35: 도로정비과 | E35: 물금읍 | F35: 32채널 NVR_5 | G35: 1
A36: 1 | B36: 재난재해-32 | C36: 3032 | D36: 산림과 | E36: 동면 | F36: 금산수질정수장 | G36: 1 | H36: 동면 금산리 1223-12 | I36: 동면 금산리 1223-12 | J36: 2023.07 | L36: 35.304793 | M36: 129.01986 | N36: 재난재해,산불
A37: 1 | B37: 재난재해-33 | C37: 3033 | D37: 산림과 | E37: 원동면 | F37: 명언마을회관 | G37: 1 | H37: 원동면 화제리 1517 | I37: 원동면 화제리 1517 | J37: 2023.07 | L37: 35.343914 | M37: 128.9796 | N37: 재난재해,산불
A38: 1 | B38: 재난재해-34 | C38: 3034 | D38: 산림과 | E38: 원동면 | F38: 배태고개 | G38: 1 | H38: 원동면 대리 산 78-7 | I38: 원동면 대리 산 78-7 | J38: 2023.07 | L38: 35.44905 | M38: 128.96064 | N38: 재난재해,산불
A39: 1 | B39: 재난재해-35 | C39: 3035 | D39: 산림과 | E39: 상북면 | F39: 소토리저수지 | G39: 1 | H39: 상북면 소토리 866 -2 | I39: 상북면 소토리 866 -2 | J39: 2023.07 | L39: 35.389095 | M39: 129.04603 | N39: 재난재해,산불
A40: 1 | B40: 재난재해-36 | C40: 3036 | D40: 산림과 | E40: 원동면 | F40: 염수봉 | G40: 1 | H40: 원동면 대리 산 90-2 | I40: 원동면 대리 산 90-2 | J40: 2023.07 | L40: 35.452779 | M40: 128.98686 | N40: 재난재해,산불
A41: 1 | B41: 재난재해-37 | C41: 3037 | D41: 산림과 | E41: 평산동 | F41: 웅상정수장 | G41: 1 | H41: 평산동 800 | I41: 평산동 800 | J41: 2023.07 | L41: 35.367408 | M41: 129.13623 | N41: 재난재해,산불
A42: 1 | B42: 재난재해-38 | C42: 3038 | D42: 산림과 | E42: 원동면 | F42: 원동중학교 | G42: 1 | H42: 원동면 원리 577 | I42: 원동면 원리 577 | J42: 2023.07 | L42: 35.375649 | M42: 128.92112 | N42: 재난재해,산불
...

Sheet VMS
A3: 개소 | B3: 구분 | C3: 관리번호 | D3: 관리부서 | E3: 행정동 | F3: 카메라명 | G3: 대수 | H3: 수정주소(도로점용) | I3: 설치 지번 | J3: 실제설치장소(주변) | K3: 설치년도 | L3: 위도 | M3: 경도
A4: =SUM(A5:A13) -> 9 | G4: =SUM(G5:G13) -> 9
A5: 1 | B5: VMS관지 - 1 | D5: 정보통계과 | E5: 중앙동 | F5: 종합운동장(석산교 방향) | G5: 1 | H5: 북부동 469-41 | I5: 북부동 533 | J5: 북부동 533(종합운동장 정문 차량 진입로 부근) | K5: 2013 | L5: 35.344399 | M5: 129.03091
A6: 1 | B6: VMS관지 - 2 | D6: 정보통계과 | E6: 동면 | F6: KCTC물류센터앞 | G6: 1 | H6: 석산리 1295-5 | I6: 석산리 1295-5 | J6: 석산리 1295-5(KCTC 맞은 편) | K6: 2013 | L6: 35.319593 | M6: 129.01864
A7: 1 | B7: VMS관지 - 3 | D7: 정보통계과 | E7: 덕계동 | F7: 덕계사거리(상행) | G7: 1 | H7: 덕계동 736-6 | I7: 덕계동 736-6 | J7: 덕계동 727(장산갈비 주차장 입구) | K7: 2013 | L7: 35.371778 | M7: 129.15088
A8: 1 | B8: VMS관지 - 4 | D8: 정보통계과 | E8: 서창동 | F8: 새마을탑삼거리 | G8: 1 | H8: 명동 749-15 | I8: 명동 736-50 | J8: 명동 736-50(매직카 자동차 정비소 맞은 편 농로 입구) | K8: 2013 | L8: 35.403993 | M8: 129.16337
A9: 1 | B9: VMS관지 - 5 | D9: 정보통계과 | E9: 물금읍 | F9: 범어주공3차 | G9: 1 | H9: 범어리 2833 | I9: 범어리 776-1 | J9: 범어리 773-1(범어 탑마트 맞은 편 부산대병원 쪽) | K9: 2013 | L9: 35.329056 | M9: 129.00484
A10: 1 | B10: VMS관지 - 6 | D10: 정보통계과 | E10: 삼성동 | F10: 양산와이어로프앞 | G10: 1 | H10: 북정동 263-29 | I10: 북정동 263-40 | J10: 북정동 263-9(양산와이어로프 앞) | K10: 2013 | L10: 35.363517 | M10: 129.04167
A11: 1 | B11: VMS관지 - 7 | D11: 정보통계과 | E11: 중앙동 | F11: 종합운동장(양산 IC 방향) | G11: 1 | H11: 북부동 154-4 | I11: 북부동 154-22 | J11: 북주동 154-11(국도 35번 삼우아파트 도로변) | K11: 2013 | L11: 35.347876 | M11: 129.03592
A12: 1 | B12: VMS관지 - 8 | D12: 정보통계과 | E12: 강서동 | F12: 협성강변타운 | G12: 1 | H12: 범어리 2271-9 | I12: 교동 978-4 | J12: 교동 245-8(협상강변아파트 101동 앞 도로변 양산천 쪽) | K12: 2013 | L12: 35.342884 | M12: 129.02644
A13: 1 | B13: VMS관지 - 9 | D13: 정보통계과 | E13: 동면 | F13: SK사송주유소앞 | G13: 1 | H13: 사송리 867-1 | I13: 사송리 355-1 | J13: 사송리 867-1(사송택지-임시도로 육교에서 부산방향으로 300m 지점) | K13: 2013 | L13: 35.308611 | M13: 129.0749

Sheet 시설물
A3: 개소 | B3: 구분 | C3: 관리번호 | D3: 관리부서 | E3: 행정동 | F3: 카메라명 | G3: 대수 | H3: 설치 지번 | I3: 실제설치장소(주변) | J3: 설치년도 | K3: 변경년도 | L3: 위도 | M3: 경도 | N3: 설치목적
A4: =SUM(A5:A32) -> 11 | G4: =SUM(G5:G30) -> 11
A5: 1 | B5: 시설물관리(방범용) | C5: 5001 | D5: 문화관광과 | E5: 중앙동 | F5: 양산대종 | G5: 1 | H5: 북부동 849 | J5: 2014 | L5: 35.343957 | M5: 129.03067 | N5: 시설물관리
A6: 1 | B6: 방범용-487 | C6: 535 | D6: 시설관리공단 | E6: 물금읍 | F6: 황산공원 미니기차길 좌1 | G6: 1 | H6: 물금읍 증산리 185-5 | J6: 2018.04 | K6: 2018 | L6: 35.299211 | M6: 128.99108 | N6: 공원관리
A7: 1 | B7: 방범용-488 | C7: 536 | D7: 시설관리공단 | E7: 물금읍 | F7: 황산공원 미니기차길 좌2 | G7: 1 | H7: 물금읍 증산리 912-1 | J7: 2018.04 | K7: 2018 | L7: 35.299045 | M7: 128.991 | N7: 공원관리
A8: 1 | B8: 방범용-489 | C8: 537 | D8: 시설관리공단 | E8: 물금읍 | F8: 황산공원 미니기차길 우1 | G8: 1 | H8: 물금읍 물금리185-16 | J8: 2018.04 | K8: 2018 | L8: 35.298968 | M8: 128.99224 | N8: 공원관리
A9: 1 | B9: 방범용-490 | C9: 538 | D9: 시설관리공단 | E9: 물금읍 | F9: 황산공원 미니기차길 우2 | G9: 1 | H9: 물금읍 증산리 922-2 | J9: 2018.04 | K9: 2018 | L9: 35.298679 | M9: 128.99218 | N9: 공원관리
A10: 1 | B10: 방범용-491 | C10: 539 | D10: 시설관리공단 | E10: 물금읍 | F10: 황산공원 미니기차 차고지 | G10: 1 | H10: 물금읍 물금리 179-22 | J10: 2018.04 | K10: 2018 | L10: 35.299248 | M10: 128.99091 | N10: 공원관리
A11: 1 | B11: 방범용-492 | C11: 540 | D11: 시설관리공단 | E11: 물금읍 | F11: 황산공원 미니기차앞 공원 | G11: 1 | H11: 물금읍 물금리 179-22 | J11: 2018.04 | K11: 2018 | L11: 35.299117 | M11: 128.99112 | N11: 공원관리
A12: 1 | B12: 방범용-493 | C12: 541 | D12: 시설관리공단 | E12: 물금읍 | F12: 황산공원 미니기차 매표소 | G12: 1 | H12: 물금읍 물금리 179-22 | J12: 2018.04 | K12: 2018 | L12: 35.299301 | M12: 128.9911 | N12: 공원관리
A13: 1 | B13: 방범용 | C13: 5002 | D13: 균형개발과 | E13: 중앙동 | F13: 신기무지개길 스마트가로등 1 | G13: 1 | H13: 북부동 776 | I13: 스마트가로등 상단 cctv | J13: 2023.06 | K13: 2023 | L13: 35.348456 | M13: 129.0476 | N13: 마을 방범
A14: 1 | B14: 방범용 | C14: 5003 | D14: 균형개발과 | E14: 중앙동 | F14: 신기무지개길 스마트가로등 2 | G14: 1 | H14: 북부동 757 | I14: 스마트가로등 상단 cctv | J14: 2023.06 | K14: 2023 | L14: 35.349681 | M14: 129.04707 | N14: 마을 방범
A15: 1 | B15: 방범용 | C15: 5004 | D15: 균형개발과 | E15: 중앙동 | F15: 신기무지개길 스마트가로등 3 | G15: 1 | H15: 북부동 712-4 | I15: 스마트가로등 상단 cctv | J15: 2023.06 | K15: 2023 | L15: 35.350232 | M15: 129.04625 | N15: 마을 방범

Sheet 주정차
A2: 개소 | B2: 관리번호 | C2: 관리부서 | D2: 행정동 | E2: 카메라명 | F2: 대수 | G2: 회전형 | H2: 고정형 | I2: 전광판 | J2: 신주소 | K2: 도로명주소 | L2: 설치 지번 | M2: 설치년월 | N2: 위도2 | O2: 경도 | P2: 설치목적
A3: =SUM(A4:A4111) -> 76 | F3: =SUM(F4:F111) -> 230 | G3: =SUM(G4:G111) -> 76 | H3: =SUM(H4:H486) -> 230 | I3: =SUM(I4:I111) -> 20
A4: 1 | B4: 8001 | C4: 교통정책과 | D4: 물금읍 | E4: 물금농협황산지점 주변 | F4: 3 | G4: 1 | H4: 3 | J4: 물금읍 삽량로 30 | K4: 범어리 2743 | L4: 물금읍 삽량로 30 | M4: 2014.01 | N4: 35.32904 | O4: 129.01233 | P4: 주정차단속
A5: 1 | B5: 8002 | C5: 교통정책과 | D5: 양주동 | E5: 양산신도시쌍용아파트 주변 | F5: 4 | G5: 1 | H5: 4 | J5: 삽량로 201 | K5: 중부동 693-5 | L5: 삽량로 201 | M5: 2014.01 | N5: 35.334589 | O5: 129.03097 | P5: 주정차단속
A6: 1 | B6: 8003 | C6: 교통정책과 | D6: 삼성동 | E6: 산막공단입구 | F6: 2 | G6: 1 | H6: 2 | J6: 산막공단로 14 | K6: 산막동 152 | L6: 북정동 168 | M6: 2014.03 | N6: 35.370737 | O6: 129.0468 | P6: 주정차단속
A7: 1 | B7: 8004 | C7: 교통정책과 | D7: 물금읍 | E7: 우미린아파트 인근 | F7: 2 | G7: 1 | H7: 2 | J7: 물금읍 범어로 77 | K7: 물금읍 범어리 2744 | L7: 범어로 77 | M7: 2014.03 | N7: 35.328795 | O7: 129.01458 | P7: 주정차단속
A8: 1 | B8: 8005 | C8: 교통정책과 | D8: 물금읍 | E8: 황산우체국 인근 | F8: 4 | G8: 1 | H8: 4 | J8: 물금읍 신주로 41 | K8: 물금읍 신주로 41 | L8: 물금읍 신주로 40 | M8: 2016.04 | N8: 35.33337 | O8: 129.01626 | P8: 주정차단속
A9: 1 | B9: 8006 | C9: 교통정책과 | D9: 물금읍 | E9: 국민연금공단사거리 | F9: 4 | G9: 1 | H9: 4 | J9: 물금읍 청운로 354 | K9: 물금읍 청운로 354 | L9: 물금읍 청운로 350 | M9: 2015.05 | N9: 35.326316 | O9: 129.01774 | P9: 주정차단속
A10: 1 | B10: 8007 | C10: 교통정책과 | D10: 물금읍 | E10: 워터파크 인근 | F10: 3 | G10: 1 | H10: 3 | J10: 물금읍 신주2길 25 | K10: 물금읍 신주2길 25 | L10: 물금읍 범어리 2727 | M10: 2015.04 | N10: 35.338079 | O10: 129.02152 | P10: 주정차단속
A11: 1 | B11: 8008 | C11: 교통정책과 | D11: 양주동 | E11: 이마트 후문 인근 | F11: 3 | G11: 1 | H11: 3 | J11: 양산역1길 14 | K11: 중부동 687-2 | L11: 양산역6길 13 | M11: 2016.04 | N11: 35.337198 | O11: 129.02768 | P11: 주정차단속
A12: 1 | B12: 8009 | C12: 교통정책과 | D12: 양주동 | E12: 이마트 정문 인근 | F12: 3 | G12: 1 | H12: 3 | J12: 양산역6길 13 | K12: 중부동 692-5 | L12: 양산역1길 14 | M12: 2014.03 | N12: 35.336306 | O12: 129.02761 | P12: 주정차단속
A13: 1 | B13: 8010 | C13: 교통정책과 | D13: 동면 | E13: 메가박스양산점 인근 | F13: 2 | G13: 1 | H13: 2 | J13: 양산역7길 10 | K13: 중부동 686-7 | L13: 양산역7길 10 | M13: 2015.04 | N13: 35.338477 | O13: 129.02703 | P13: 주정차단속
A14: 1 | B14: 8011-1 | C14: 교통정책과 | D14: 동면 | E14: GOOD프라임빌딩 앞 사거리 | F14: 4 | G14: 1 | H14: 4 | J14: 동면 금오로 242 | K14: 동면 석산리 1477-1 | L14: 동면 금오로 242 | M14: 2015.04 | N14: 35.315608 | O14: 129.0254 | P14: 주정차단속
A15: 1 | B15: 8012 | C15: 교통정책과 | D15: 삼성동 | E15: 북정동 네오파트 앞 | F15: 3 | G15: 1 | H15: 3 | J15: 북정로 24 | K15: 북정동 890-4 | L15: 북정로 24 | M15: 2014.03 | N15: 35.358965 | O15: 129.04262 | P15: 주정차단속
A16: 1 | B16: 8013 | C16: 교통정책과 | D16: 삼성동 | E16: 삼성동주민센터 인근 | F16: 2 | G16: 1 | H16: 2 | J16: 신기서길 27 | K16: 신기동 508-5 | L16: 신기서길 27 | M16: 2014.03 | N16: 35.35281 | O16: 129.04062 | P16: 주정차단속
A17: 1 | B17: 8014 | C17: 교통정책과 | D17: 중앙동 | E17: 상공회의소 인근 | F17: 2 | G17: 1 | H17: 2 | J17: 중앙로 209 | K17: 북부동 687-10 | L17: 중앙로 209 | M17: 2014.03 | N17: 35.349153 | O17: 129.04022 | P17: 주정차단속
A18: 1 | B18: 8015 | C18: 교통정책과 | D18: 중앙동 | E18: 신한은행 앞 | F18: 2 | G18: 1 | H18: 2 | J18: 중앙로 177 | K18: 북부동 483-4 | M18: 2014.03 | N18: 35.346461 | O18: 129.0391 | P18: 주정차단속
A19: 1 | B19: 8016 | C19: 교통정책과 | D19: 중앙동 | E19: 경남은행 사거리 주변 | F19: 4 | G19: 1 | H19: 4 | J19: 삼일로 101 | K19: 북부동 422-28 | L19: 삼일로 101 | M19: 2014.03 | N19: 35.344112 | O19: 129.0384 | P19: 주정차단속
A20: 1 | B20: 8017 | C20: 교통정책과 | D20: 중앙동 | E20: 남부시장 인근 | F20: 2 | G20: 1 | H20: 2 | J20: 중앙로 128 | K20: 중앙로 130 | L20: 중앙로 128 | M20: 2014.03 | N20: 35.342008 | O20: 129.0377 | P20: 주정차단속
A21: 1 | B21: 8018 | C21: 교통정책과 | D21: 중앙동 | E21: 구 터미널 인근 | F21: 2 | G21: 1 | H21: 2 | J21: 삼일로 67 | K21: 북부동 462-32 | L21: 삼일로 67 | M21: 2014.03 | N21: 35.343838 | O21: 129.03495 | P21: 주정차단속
A22: 1 | B22: 8019 | C22: 교통정책과 | D22: 양주동 | E22: 주공7차 사거리 주변 | F22: 2 | G22: 1 | H22: 2 | J22: 양주로 46 | K22: 양주로 46 | L22: 남부동 565-2 | M22: 2014.03 | N22: 35.331859 | O22: 129.02592 | P22: 주정차단속
A23: 1 | B23: 8020 | C23: 교통정책과 | D23: 물금읍 | E23: 범어대동 삼거리 주변 | F23: 3 | G23: 1 | H23: 3 | J23: 물금읍 오봉로 165 | K23: 물금읍 범어리 682-1 | L23: 물금읍 오봉로 165 | M23: 2014.03 | N23: 35.335098 | O23: 129.00577 | P23: 주정차단속
A24: 1 | B24: 8021 | C24: 교통정책과 | D24: 물금읍 | E24: 물금역주변 | F24: 4 | G24: 1 | H24: 4 | J24: 물금읍 황산로 338 | K24: 물금읍 황산로 338 | L24: 물금읍 황산로 338 | M24: 2017.01 | N24: 35.30749 | O24: 128.98557 | P24: 주정차단속
A25: 1 | B25: 8022 | C25: 교통정책과 | D25: 물금읍 | E25: 양우내안애2차아파트 주변 | F25: 3 | G25: 1 | H25: 3 | J25: 물금읍 물금로 178 | K25: 물금읍 가촌리 1269-4 | L25: 물금읍 물금로 178 | M25: 2017.01 | N25: 35.317371 | O25: 128.99997 | P25: 주정차단속
A26: 1 | B26: 8023 | C26: 교통정책과 | D26: 물금읍 | E26: 힐데스하임 앞 사거리 | F26: 4 | G26: 1 | H26: 4 | J26: 물금읍 야리로 75 | K26: 범어리 2786-5 | L26: 새실1길 50 | M26: 2016.04 | N26: 35.31664 | O26: 129.00747 | P26: 주정차단속
A27: 1 | B27: 8024 | C27: 교통정책과 | D27: 동면 | E27: 양산제일병원 인근 | F27: 2 | G27: 1 | H27: 2 | J27: 동면 금오로 255 | K27: 동면 석산리 1492 | L27: 동면 금오로 255 | M27: 2017.07 | N27: 35.316257 | O27: 129.0275 | P27: 주정차단속
A28: 1 | B28: 8025 | C28: 교통정책과 | D28: 물금읍 | E28: CGV양산물금점 인근 | F28: 2 | G28: 1 | H28: 2 | J28: 물금읍 백호로 70 | K28: 물금읍 가촌리 1269-13 | L28: 물금읍 백호로 70 | M28: 2018.03 | N28: 35.318118 | O28: 129.0023 | P28: 주정차단속
A29: 1 | B29: 8026 | C29: 교통정책과 | D29: 물금읍 | E29: 양우1,2차 상가 주변 | F29: 2 | G29: 1 | H29: 2 | J29: 물금읍 야리로 21 | K29: 물금읍 가촌리 1279-7 | L29: 물금읍 야리로 21 | M29: 2018.03 | N29: 35.317331 | O29: 129.00088 | P29: 주정차단속
A30: 1 | B30: 8027 | C30: 교통정책과 | D30: 물금읍 | E30: 증산역 앞 사거리 | F30: 4 | G30: 1 | H30: 4 | J30: 물금읍 증산역로 163 | K30: 물금읍 증산역로 163 | L30: 물금읍 증산역로 163 | M30: 2018.03 | N30: 35.309185 | O30: 129.00726 | P30: 주정차단속
A31: 1 | B31: 8028 | C31: 교통정책과 | D31: 동면 | E31: 석산 동원2차 사거리 | F31: 4 | G31: 1 | H31: 4 | J31: 동면 금오16길 4 | K31: 동면 석산리 1448-5 | L31: 동면 금오16길 4 | M31: 2018.03 | N31: 35.317964 | O31: 129.0256 | P31: 주정차단속
A32: 1 | B32: 8029 | C32: 교통정책과 | D32: 동면 | E32: 석산 e편한2차 삼거리 | F32: 3 | G32: 1 | H32: 3 | J32: 동면 금오13길 54 | K32: 석산리 1449-1 | L32: 동면 금오13길 54 | M32: 2018.03 | N32: 35.320493 | O32: 129.02437 | P32: 주정차단속
A33: 1 | B33: 8030 | C33: 교통정책과 | D33: 물금읍 | E33: MK프라자 앞 | F33: 3 | G33: 1 | H33: 3 | J33: 물금읍 메기로 190 | K33: 물금읍 증산리 1820 | L33: 물금읍 메기로 190 | M33: 2018.11 | N33: 35.310777 | O33: 129.01064 | P33: 주정차단속
A34: 1 | B34: 8031 | C34: 교통정책과 | D34: 물금읍 | E34: 이지더원5차 사거리 주변 | F34: 4 | G34: 1 | H34: 4 | J34: 물금읍 물금로 60 | K34: 물금읍 물금리 898-2 | L34: 물금읍 물금로 60 | M34: 2019.05 | N34: 35.311399 | O34: 128.99125 | P34: 주정차단속
A35: 1 | B35: 8032 | C35: 교통정책과 | D35: 물금읍 | E35: 이지더원1차 사거리 주변 | F35: 4 | G35: 1 | H35: 4 | J35: 물금읍 새실로 53 | K35: 물금읍 새실로 53 | L35: 물금읍 가촌리 1279-8 | M35: 2019.05 | N35: 35.312051 | O35: 128.99687 | P35: 주정차단속
... A42: 1 | B42: 8039 | C42: 교통정책과 | D42: 물금읍 | E42: 양산부산대병원 인근 | F42: 3 | G42: 1 | H42: 3 | J42: 물금읍 금오로 20 | K42: 물금읍 범어리 2742 | L42: 물금읍 금오로 20 | M42: 2016.04 | N42: 35.326381 | O42: 129.01102 | P42: 주정차단속
A43: 1 | B43: 8040 | C43: 교통정책과 | D43: 물금읍 | E43: 반도유보라4차 사거리 | F43: 4 | G43: 1 | H43: 4 | J43: 물금읍 백호로 91 | K43: 물금읍 백호로 91 | M43: 2016.04 | N43: 35.317185 | O43: 129.00344 | P43: 주정차단속
A44: 1 | B44: 8041 | C44: 교통정책과 | D44: 물금읍 | E44: 양우1차 사거리 | F44: 4 | G44: 1 | H44: 4 | J44: 물금읍 야리로 31 | K44: 물금읍 야리로 31 | L44: 물금읍 야리로 31 | M44: 2016.04 | N44: 35.316227 | O44: 129.00212 | P44: 주정차단속
A45: 1 | B45: 8042 | C45: 교통정책과 | D45: 물금읍 | E45: 반도4차후문 사거리 | F45: 4 | G45: 1 | H45: 4 | J45: 물금읍 새실1길 50 | K45: 물금읍 범어리 2786-5 | L45: 물금읍 새실1길 50 | M45: 2017.01 | N45: 35.315968 | O45: 129.00751 | P45: 주정차단속
A46: 1 | B46: 8043 | C46: 교통정책과 | D46: 물금읍 | E46: 부산대양산캠퍼스역 | F46: 3 | G46: 1 | H46: 3 | J46: 물금읍 메기로 270 | K46: 물금읍 부산대학로 156 | L46: 물금읍 메기로 270 | M46: 2016.04 | N46: 35.315401 | O46: 129.01266 | P46: 주정차단속
A47: 1 | B47: 8044 | C47: 교통정책과 | D47: 동면 | E47: 남양산 맥도날드 인근 | F47: 2 | G47: 1 | H47: 2 | J47: 동면 남양산길 7 | K47: 동면 석산리 1421-9 | L47: 동면 남양산길 7 | M47: 2016.04 | N47: 35.328259 | O47: 129.03385 | P47: 주정차단속
...

Sheet 신호등교차로cctv
A1: 개소 | B1: 관리번호 | C1: 카메라명 | D1: 행정동 | E1: 대수 | F1: PTZ (회전형) | G1: 고정형 | H1: 수정 주소(도로점용 관련) | I1: 실제설치장소(주변) | J1: 위도 | K1: 경도
A2: =SUM(A3:A99) -> 51 | E2: =SUM(E3:E54) -> 51 | F2: =SUM(F3:F54) -> 7 | G2: =SUM(G3:G54) -> 44
A3: 1 | B3: 7001 | C3: 가양초등학교앞 | D3: 물금읍 | E3: =SUM(F3:G3) -> 1 | G3: 1 | H3: 물금리 898-2 | I3: 가양초등학교 대각선 맞은편 큰 사거리(횡단보도 위 고정카메라) | J3: 35.311379 | K3: 128.9915
A4: 1 | B4: 7002 | C4: 대방7차옆사거리(돔) | D4: 물금읍 | E4: =SUM(F4:G4) -> 1 | F4: 1 | H4: 가촌리 1279-9 | I4: 물금중학교 사거리 | J4: 35.313852 | K4: 128.9941
A5: 1 | B5: 7003 | C5: 석계교차로(고정) | D5: 상북면 | E5: =SUM(F5:G5) -> 1 | G5: 1 | H5: 상북면 석계리 553-3 | I5: 석계산단 교차로 | J5: 35.405999 | K5: 129.05604
A6: 1 | B6: 7004 | C6: 양우1차사거리 | D6: 물금읍 | E6: =SUM(F6:G6) -> 1 | G6: 1 | H6: 가촌리 1280-8 | I6: 아르누보시티 빌딩 입구 | J6: 35.316165 | K6: 129.00232
A7: 1 | B7: 7005 | C7: 이지더원2차옆사거리(돔) | D7: 물금읍 | E7: =SUM(F7:G7) -> 1 | F7: 1 | H7: 물금리 898-2 | I7: 가양초등학교 대각선 맞은편 큰 사거리(모서리 폴대 위 돔 카메라) | J7: 35.311249 | K7: 128.99159
A8: 1 | B8: 7006 | C8: 계석교차로(돔) | D8: 동면 | E8: =SUM(F8:G8) -> 1 | F8: 1 | H8: 석산리 1536 | I8: 계석교차로(육교 계단 앞) | J8: 35.328191 | K8: 129.03431
A9: 1 | B9: 7007 | C9: 대방노블랜드(고정) | D9: 물금읍 | E9: =SUM(F9:G9) -> 1 | G9: 1 | H9: 가촌리 1279-8 | I9: 양우내안애1차 버스정류장(물금농협가촌리지점방면) | J9: 35.314586 | K9: 129.00033
A10: 1 | B10: 7008 | C10: 대방노블랜드7차(고정) | D10: 물금읍 | E10: =SUM(F10:G10) -> 1 | G10: 1 | H10: 황산로 453 | I10: 이디야커피 | J10: 35.315391 | K10: 128.99127
A11: 1 | B11: 7009 | C11: 범어교차로(돔) | D11: 물금읍 | E11: =SUM(F11:G11) -> 1 | F11: 1 | H11: 범어리 2763 | I11: 범어초등학교 버스정류장(경민아파트방면) | J11: 35.330741 | K11: 129.00731
A12: 1 | B12: 7010 | C12: 서창산업단지(돔) | D12: 서창동 | E12: =SUM(F12:G12) -> 1 | F12: 1 | H12: 주남로 147 | I12: 주남로 147 | J12: 35.423438 | K12: 129.15584
A13: 1 | B13: 7011 | C13: 웅상롯데캐슬(돔) | D13: 소주동 | E13: =SUM(F13:G13) -> 1 | F13: 1 | H13: 주진동 49-2 | I13: 양산롯데캐슬입구 버스정류장(웅상문화체육센터입구 방면) | J13: 35.394555 | K13: 129.15957
A14: 1 | B14: 7012 | C14: 회야교교차로(돔) | D14: 서창동 | E14: =SUM(F14:G14) -> 1 | F14: 1 | H14: 용당동 390-6 | I14: 웅비공업지구 버스정류장(용당마을 방면) | J14: 35.434057 | K14: 129.19022
A15: 1 | B15: 7013 | C15: 호포삼거리(부도로) | D15: 동면 | E15: =SUM(F15:G15) -> 1 | G15: 1 | H15: 동면 가산리 436-5 | I15: 호포역 건너편 꽃집 앞 | J15: 35.280327 | K15: 129.01668
A16: 1 | B16: 7014 | C16: 가산중리마을2(주도로) | D16: 동면 | E16: =SUM(F16:G16) -> 1 | G16: 1 | H16: 동면 가산리 784-10 | I16: 가산중리마을 교차로 | J16: 35.295149 | K16: 129.02052
A17: 1 | B17: 7014 | C17: 가산중리마을2(부도로) | D17: 동면 | E17: =SUM(F17:G17) -> 1 | G17: 1 | H17: 동면 가산리 784-10 | I17: 가산중리마을 교차로
A18: 1 | B18: 7015 | C18: 영락교회앞(주도로) | D18: 동면 | E18: =SUM(F18:G18) -> 1 | G18: 1 | H18: 동면 가산리 847-16 | I18: 영락교회 | J18: 35.298165 | K18: 129.02122
A19: 1 | B19: 7015 | C19: 영락교회앞(부도로) | D19: 동면 | E19: =SUM(F19:G19) -> 1 | G19: 1 | H19: 동면 가산리 847-16 | I19: 영락교회
A20: 0 | B20: 7016 | C20: 금산2교차로(부도로) | D20: 동면 | E20: =SUM(F20:G20) -> 0 | G20: 0 | H20: 동면 금산리 1098-11 | I20: 금산2교차로 | J20: 35.301502 | K20: 129.02267
A21: 1 | B21: 7016 | C21: 금산2교차로(주도로) | D21: 동면 | E21: =SUM(F21:G21) -> 1 | G21: 1 | H21: 동면 금산리 1098-11 | I21: 금산2교차로
A22: 1 | B22: 7017 | C22: 금산3교차로(주도로) | D22: 동면 | E22: =SUM(F22:G22) -> 1 | G22: 1 | H22: 동면 금산리 1485 | I22: 금산2교 | J22: 35.305742 | K22: 129.02555
A23: 1 | B23: 7017 | C23: 금산3교차로(부도로) | D23: 동면 | E23: =SUM(F23:G23) -> 1 | G23: 1 | H23: 동면 금산리 1485 | I23: 금산2교
A24: 1 | B24: 7018 | C24: 금산교차로(부도로) | D24: 동면 | E24: =SUM(F24:G24) -> 1 | G24: 1 | H24: 동면 금산리 581-3 | I24: 금산교차로 | J24: 35.30818 | K24: 129.02689
A25: 1 | B25: 7018 | C25: 금산교차로(주도로) | D25: 동면 | E25: =SUM(F25:G25) -> 1 | G25: 1 | H25: 동면 금산리 581-3 | I25: 금산교차로
A26: 1 | B26: 7019 | C26: 석산교차로(주도로) | D26: 동면 | E26: =SUM(F26:G26) -> 1 | G26: 1 | H26: 동면 석산리 1505 | I26: 이편한세상1차 103동 앞 | J26: 35.31894 | K26: 129.02937
A27: 1 | B27: 7020 | C27: 일맥교앞교차로(주도로) | D27: 상북면 | E27: =SUM(F27:G27) -> 1 | G27: 1 | H27: 상북면 소토리 1287-51 | I27: 일랙교 | J27: 35.385133 | K27: 129.05081
A28: 1 | B28: 7020 | C28: 일맥교앞교차로(부도로) | D28: 상북면 | E28: =SUM(F28:G28) -> 1 | G28: 1 | H28: 상북면 소토리 1287-51 | I28: 일랙교
A29: 1 | B29: 7021 | C29: 용주사입구(부도로) | D29: 상북면 | E29: =SUM(F29:G29) -> 1 | G29: 1 | H29: 상북면 신전리 산 14-5 | I29: 용주사입구 교차로 | J29: 35.425144 | K29: 129.06579
A30: 1 | B30: 7022 | C30: 신전마을입구삼거리(부도로) | D30: 하북면 | E30: =SUM(F30:G30) -> 1 | G30: 1 | H30: 하북면 용연리 1159 | I30: 신전마을입구 교차로 | J30: 35.431653 | K30: 129.06756
A31: 1 | B31: 7022 | C31: 신전마을입구삼거리(주도로) | D31: 하북면 | E31: =SUM(F31:G31) -> 1 | G31: 1 | H31: 하북면 용연리 1159 | I31: 신전마을입구 교차로
A32: 1 | B32: 7023 | C32: 양산휴게소앞(부도로) | D32: 하북면 | E32: =SUM(F32:G32) -> 1 | G32: 1 | H32: 하북면 용연리 1150 | I32: 양산휴게소 | J32: 35.436514 | K32: 129.07007
A33: 1 | B33: 7023 | C33: 양산휴게소앞(주도로) | D33: 하북면 | E33: =SUM(F33:G33) -> 1 | G33: 1 | H33: 하북면 용연리 1150 | I33: 양산휴게소
A34: 1 | B34: 7024 | C34: 내원사입구(부도로) | D34: 하북면 | E34: =SUM(F34:G34) -> 1 | G34: 1 | H34: 하북면 용연리 775-3 | I34: 내원사입구 교차로 | J34: 35.439868 | K34: 129.07168
A35: 1 | B35: 7025 | C35: 용연로삼거리(부도로) | D35: 하북면 | E35: =SUM(F35:G35) -> 1 | G35: 1 | H35: 하북면 용연리 788-1 | I35: 진이네 해물칼국수 | J35: 35.442838 | K35: 129.07223
A36: 1 | B36: 7026 | C36: 삼감마을입구(부도로) | D36: 하북면 | E36: =SUM(F36:G36) -> 1 | G36: 1 | H36: 하북면 백록리 1253-18 | I36: 삼감마을입구 교차로 | J36: 35.448981 | K36: 129.07376
A37: 1 | B37: 7027 | C37: 녹동마을입구(부도로) | D37: 하북면 | E37: =SUM(F37:G37) -> 1 | G37: 1 | H37: 하북면 백록리 1040-1 | I37: 녹동마을입구 교차로 | J37: 35.45415 | K37: 129.07664
A38: 1 | B38: 7028 | C38: 대영소결금속앞삼거리(부도로) | D38: 하북면 | E38: =SUM(F38:G38) -> 1 | G38: 1 | H38: 하북면 백록리 1045-15 | I38: 대영소결금속 | J38: 35.459856 | K38: 129.07917
A39: 1 | B39: 7029 | C39: 백록새동네입구(부도로) | D39: 하북면 | E39: =SUM(F39:G39) -> 1 | G39: 1 | H39: 하북면 백록리 654-56 | I39: 백록새동네 교차로 | J39: 35.473074 | K39: 129.08596
A40: 1 | B40: 7030 | C40: 공원묘지삼거리(부도로) | D40: 하북면 | E40: =SUM(F40:G40) -> 1 | G40: 1 | H40: 하북면 답곡리 701-2 | I40: 공원묘지삼거리 | J40: 35.475337 | K40: 129.08702
...
